Workbook

Sheet Mode d'emploi
A1: BARÈME DE POINTS — MESURER LE TRAVAIL DES TECHNICIENS, PAS LE PRIX
A3: Chaque type de tâche vaut des points selon le temps et la difficulté réels, pas selon ce qu'elle rapporte.
A4: La facturation ne change pas : les euros restent dans ton Excel pour les clients. Les points servent seulement à comparer les techniciens entre eux, de façon juste.
A6: CE QUE TU AS À FAIRE
A7: 1. Onglet « Familles » : corrige les temps de la colonne D (cases jaunes). Ce sont des estimations de départ, à valider avec les techniciens.
A8: 2. Onglet « Prestations » : si une prestation ne correspond pas à sa famille, change sa famille (liste en colonne F) ou mets un temps à part en colonne H (cases jaunes).
A9: 3. Les réglages ci-dessous (cases jaunes) : valeur d'un point, durée de la journée, majoration de nuit.
A10: 4. Onglet « Exemple » : une journée type pour voir le calcul. Tu peux y changer les codes et les quantités.
A12: Cases jaunes, chiffres en bleu = à saisir ou à corriger. Chiffres en noir = calculés, ne pas modifier.
A14: RÉGLAGES
A15: Minutes de travail pour 1 point | B15: 15 | C15: 1 point = 15 minutes de travail normal. Proposition à valider.
A16: Heures de travail dans une journée | B16: 7 | C16: Journée de référence pour calculer le taux. Proposition à valider.
A17: Points attendus pour une journée | B17: =HeuresJour*60/MinParPoint -> 28 | C17: Calculé : une journée normale vaut ce nombre de points (100 %).
A18: Majoration pour une intervention de nuit (HNO) | B18: 0.25 | C18: Proposition : +25 % sur les prestations de nuit, pour la pénibilité. Mets 0 % pour ne rien majorer.
A19: Bonus « intervention difficile » | B19: 0.5 | C19: Pour plus tard : bonus que le technicien demande et que tu valides. Pas encore utilisé dans le calcul.
A21: POURQUOI C'EST PLUS JUSTE
A22: • Un technicien est comparé à la journée de référence, pas aux tarifs du client : 28 points sur une journée de 7 h = 100 %, quel que soit le projet.
A23: • Les tâches longues ou difficiles rapportent autant de points que le temps qu'elles demandent, même si elles sont mal payées.
A24: • Les congés et absences sont retirés des jours travaillés : ils ne font pas baisser le taux.
A25: • Au bout d'un mois, on pourra comparer ces temps avec la réalité et ajuster le barème.

Sheet Familles
A1: FAMILLES DE TÂCHES ET TEMPS STANDARDS
A2: Corrige seulement la colonne D (minutes par unité). Les points et le nombre de prestations se calculent seuls.
A4: Famille | B4: Ce qui est compté | C4: Exemples de prestations | D4: Temps estimé (min / unité) | E4: Points / unité | F4: Nb de prestations | G4: Remarque
A5: Ticket intervention | B5: par ticket | C5: Ticket | D5: 120 | E5: =D5/MinParPoint -> 8 | F5: =COUNTIF(Prestations!$F$5:$F$256,A5) -> 5 | G5: Ticket de maintenance : déplacement local, diagnostic, réparation simple.
A6: Malfaçon aérien | B6: par ticket | C6: Malfaçon aérien | D6: 150 | E6: =D6/MinParPoint -> 10 | F6: =COUNTIF(Prestations!$F$5:$F$256,A6) -> 2 | G6: Reprise en hauteur (échelle ou nacelle).
A7: Malfaçon souterrain | B7: par ticket | C7: Malfaçon souterrain | D7: 90 | E7: =D7/MinParPoint -> 6 | F7: =COUNTIF(Prestations!$F$5:$F$256,A7) -> 2 | G7: Reprise en chambre.
A8: Heure de technicien | B8: par heure | C8: RHD57 · Heure technicien HO · intervention immédiate · RHD57 · Heure technicien HO · intervention programmée · RHD57 · Heure technicien HNO | D8: 60 | E8: =D8/MinParPoint -> 4 | F8: =COUNTIF(Prestations!$F$5:$F$256,A8) -> 8 | G8: Prestations facturées à l'heure : 1 h = 1 h de travail. En binôme, chaque technicien saisit sa ligne.
A9: City Fast N1 · site (PM, DME) | B9: par intervention | C9: City Fast N1 Site (PM, DME) · Urgente 4h · HO 7h-19h · City Fast N1 Site (PM, DME) · Urgente 4h · HNO 19h-7h · City Fast N1 Site (PM, DME) · Standard Plus 24h · HO 7h-19h | D9: 180 | E9: =D9/MinParPoint -> 12 | F9: =COUNTIF(Prestations!$F$5:$F$256,A9) -> 4 | G9: Délai (urgent, standard) et horaire ne changent pas le travail : seule l'heure de nuit est majorée (voir Réglages).
A10: City Fast N2 · BPE en chambre | B10: par intervention | C10: City Fast N2 Extrémité câble en chambre (BPE) · Urgente 4h · HO 7h-19h · City Fast N2 Extrémité câble en chambre (BPE) · Urgente 4h · HNO 19h-7h · City Fast N2 Extrémité câble en chambre (BPE) · Standard Plus 24h · HO 7h-19h | D10: 240 | E10: =D10/MinParPoint -> 16 | F10: =COUNTIF(Prestations!$F$5:$F$256,A10) -> 4
A11: City Fast N3 · câble en conduite | B11: par intervention | C11: City Fast N3 Câble en conduite (tirage) · Urgente 4h · HO 7h-19h · City Fast N3 Câble en conduite (tirage) · Urgente 4h · HNO 19h-7h · City Fast N3 Câble en conduite (tirage) · Standard Plus 24h · HO 7h-19h | D11: 360 | E11: =D11/MinParPoint -> 24 | F11: =COUNTIF(Prestations!$F$5:$F$256,A11) -> 4 | G11: Tirage de câble : souvent une grosse demi-journée.
A12: SAV niveau 0 | B12: par intervention | C12: SAV F0 · Niveau 0 · SAV F0 · Niveau 0 en HNO | D12: 90 | E12: =D12/MinParPoint -> 6 | F12: =COUNTIF(Prestations!$F$5:$F$256,A12) -> 2
A13: SAV niveau 1 | B13: par intervention | C13: SAV F1 · Niveau 1 (inclut F0) · SAV F1 · Niveau 1 en HNO (inclut F0) | D13: 180 | E13: =D13/MinParPoint -> 12 | F13: =COUNTIF(Prestations!$F$5:$F$256,A13) -> 2 | G13: Inclut le niveau 0.
A14: SAV niveau 2 | B14: par intervention | C14: SAV F2 · Niveau 2 (inclut F1) · SAV F2 · Niveau 2 en HNO (inclut F1) | D14: 300 | E14: =D14/MinParPoint -> 20 | F14: =COUNTIF(Prestations!$F$5:$F$256,A14) -> 2 | G14: Inclut le niveau 1.
A15: Raccordement entreprise en immeuble | B15: par raccordement | C15: Super forfait · FTTE · Super forfait · lien supplémentaire · 46.1 · Entreprise en immeuble · avec route optique | D15: 360 | E15: =D15/MinParPoint -> 24 | F15: =COUNTIF(Prestations!$F$5:$F$256,A15) -> 7 | G15: 46.x, 47.x, 59.1 FTTE, super forfait FTTE et lien supplémentaire.
A16: Raccordement entreprise avec extension (Z50 à Z200) | B16: par raccordement | C16: Super forfait · Z100 (NEW) · Super forfait · Z200 (NEW) · 48.1 · Entreprise Z50 · 4 FO · avec route optique | D16: 600 | E16: =D16/MinParPoint -> 40 | F16: =COUNTIF(Prestations!$F$5:$F$256,A16) -> 14 | G16: 48.x à 53.x et super forfaits Z100 / Z200. Le câble posé en plus se compte au mètre.
A17: Raccordement FTTH Pro | B17: par raccordement | C17: 60.1 · FTTH Pro · raccordement immeuble (création PTO) · 60.2 · FTTH Pro · raccordement chambre / poteau / façade · 60.4 · FTTH Pro · raccordement PTO existante | D17: 180 | E17: =D17/MinParPoint -> 12 | F17: =COUNTIF(Prestations!$F$5:$F$256,A17) -> 5 | G17: 60.1 à 60.5, 62.9 (création ou déplacement de PTO).
A18: Petite intervention équipement | B18: par intervention | C18: 56.2 · Changement et mise en service de CPE · 56.3 · Installation équipement client opérateur (forfait 2 h) · 57.1 · Résiliation entreprise (récupération CPE) | D18: 60 | E18: =D18/MinParPoint -> 4 | F18: =COUNTIF(Prestations!$F$5:$F$256,A18) -> 7 | G18: CPE, ONT, tiroir, résiliation, upgrade simple.
A19: Mise en service / upgrade | B19: par intervention | C19: 56.1 · Entreprise upgrade (intervention physique) · 60.8 · Mise en service FTTE sur lien existant (réseau tiers) | D19: 120 | E19: =D19/MinParPoint -> 8 | F19: =COUNTIF(Prestations!$F$5:$F$256,A19) -> 2 | G19: 56.1 upgrade, 60.8 mise en service FTTE.
A20: Visite technique | B20: par visite | C20: 61.1 · Visite technique FTTH Pro · cas simple · 61.2 · Visite technique FTTH Pro · cas complexe (aiguillage) · 61.3 · Visite technique · option aiguillage | D20: 90 | E20: =D20/MinParPoint -> 6 | F20: =COUNTIF(Prestations!$F$5:$F$256,A20) -> 3 | G20: 61.1 à 61.3.
A21: Câble posé ou tiré | B21: par mètre | C21: 55.1 · Raccordement long / extension · câble 4 FO (au ml) · 55.2 · Extension du réseau · câble 12 FO (au ml) · 55.3 · Extension du réseau · câble 24 FO (au ml) | D21: 1 | E21: =D21/MinParPoint -> 0.066666667 | F21: =COUNTIF(Prestations!$F$5:$F$256,A21) -> 20 | G21: Conduite, aérien, façade, immeuble, extension. 1 min/m ≈ 400 m par jour.
A22: Aiguillage / dépose / portage de câble | B22: par mètre | C22: 11.6 · Portage de câble (au ml) · 11.9 · Aiguillage de conduite existante (études) · 11.10 · Dépose de câble (au ml) | D22: 0.5 | E22: =D22/MinParPoint -> 0.033333333 | F22: =COUNTIF(Prestations!$F$5:$F$256,A22) -> 3
A23: Chemin de câble, goulotte, gaine | B23: par mètre | C23: 62.2 · Goulotte, fourniture + pose (au ml) · 12.1 · Chemin de câble cablofil 50×50 sur équerre (au ml) · 12.2 · Gaine fendue (au ml) | D23: 5 | E23: =D23/MinParPoint -> 0.33333333 | F23: =COUNTIF(Prestations!$F$5:$F$256,A23) -> 6 | G23: Fixation au mur ou au plafond.
A24: Percement simple | B24: par percement | C24: 12.5 · Percement cloison / mur parpaing | D24: 30 | E24: =D24/MinParPoint -> 2 | F24: =COUNTIF(Prestations!$F$5:$F$256,A24) -> 1 | G24: Cloison, parpaing.
A25: Carottage / percement spécifique | B25: par percement | C25: 62.3 · Percement spécifique (traversée d'étage, carottage) · 12.6 · Carottage de mur béton armé | D25: 90 | E25: =D25/MinParPoint -> 6 | F25: =COUNTIF(Prestations!$F$5:$F$256,A25) -> 2 | G25: Béton armé, traversée d'étage.
A26: Soudure à la fibre | B26: par fibre | C26: 15.14 · Joint blanc (lovage) · soudure supplémentaire (à la fibre) · 16.14 · Joint blanc (tubes) · soudure supplémentaire (à la fibre) · 17.2 · Soudure supplémentaire (rentrée dans boîte existante) | D26: 3 | E26: =D26/MinParPoint -> 0.2 | F26: =COUNTIF(Prestations!$F$5:$F$256,A26) -> 5 | G26: Soudures supplémentaires.
A27: Boîte d'épissure (joint) jusqu'à 48 FO | B27: par boîte | C27: 14.10 · Joint droit · 48 FO · 14.11 · Joint droit · 36 FO · 14.12 · Joint droit · 24 FO | D27: 120 | E27: =D27/MinParPoint -> 8 | F27: =COUNTIF(Prestations!$F$5:$F$256,A27) -> 13 | G27: Joints droits ou blancs (lovage, tubes).
A28: Boîte d'épissure (joint) 72 à 144 FO | B28: par boîte | C28: 14.7 · Joint droit · 144 FO · 14.8 · Joint droit · 96 FO · 14.9 · Joint droit · 72 FO | D28: 240 | E28: =D28/MinParPoint -> 16 | F28: =COUNTIF(Prestations!$F$5:$F$256,A28) -> 9
A29: Boîte d'épissure (joint) 192 à 288 FO | B29: par boîte | C29: 14.5 · Joint droit · 288 FO · 14.6 · Joint droit · 192 FO · 15.5 · Joint blanc (lovage) · 288 FO | D29: 360 | E29: =D29/MinParPoint -> 24 | F29: =COUNTIF(Prestations!$F$5:$F$256,A29) -> 6
A30: Boîte d'épissure (joint) 432 FO et plus | B30: par boîte | C30: 14.1 · Joint droit · 864 FO · 14.2 · Joint droit · 720 FO · 14.3 · Joint droit · 576 FO | D30: 600 | E30: =D30/MinParPoint -> 40 | F30: =COUNTIF(Prestations!$F$5:$F$256,A30) -> 12 | G30: Souvent plus d'une journée.
A31: Rentrée / piquage dans une BPE | B31: par intervention | C31: 58.1 · Intervention sur BPE non identifiée · 58.2 · Intervention sur BPE identifiée (supplémentaire) · 17.1 · Rentrée + soudures dans boîte existante (2 à 12 FO) | D31: 120 | E31: =D31/MinParPoint -> 8 | F31: =COUNTIF(Prestations!$F$5:$F$256,A31) -> 5 | G31: 17.1, 17.3, 17.5, 58.x.
A32: Fermeture / fixation de BPE | B32: par boîte | C32: 17.7 · Fermeture / fixation de BPE + étiquetage | D32: 30 | E32: =D32/MinParPoint -> 2 | F32: =COUNTIF(Prestations!$F$5:$F$256,A32) -> 1
A33: Audit BPE jusqu'à 288 FO | B33: par boîte | C33: 18.1 · Audit et récolement BPE complet jusqu'à 72 FO · 18.2 · Audit et récolement BPE complet jusqu'à 144 FO · 18.3 · Audit et récolement BPE complet jusqu'à 288 FO | D33: 90 | E33: =D33/MinParPoint -> 6 | F33: =COUNTIF(Prestations!$F$5:$F$256,A33) -> 3
A34: Audit BPE plus de 288 FO | B34: par boîte | C34: 18.4 · Audit et récolement BPE complet jusqu'à 432 FO · 18.5 · Audit et récolement BPE complet jusqu'à 720 FO · 18.6 · Audit et récolement BPE complet jusqu'à 864 FO | D34: 150 | E34: =D34/MinParPoint -> 10 | F34: =COUNTIF(Prestations!$F$5:$F$256,A34) -> 3
A35: Récolement lors de modification | B35: par boîte | C35: 18.7 · Récolement BPE complet lors de modification | D35: 45 | E35: =D35/MinParPoint -> 3 | F35: =COUNTIF(Prestations!$F$5:$F$256,A35) -> 1
A36: Tête de câble jusqu'à 24 FO | B36: par tête | C36: 19.6 · Raccordement de tête de câble · 24 FO · 19.7 · Raccordement de tête de câble · 12 FO · 19.8 · Raccordement de tête de câble · 6 FO | D36: 120 | E36: =D36/MinParPoint -> 8 | F36: =COUNTIF(Prestations!$F$5:$F$256,A36) -> 5
A37: Tête de câble 36 à 72 FO | B37: par tête | C37: 19.3 · Raccordement de tête de câble · 72 FO · 19.4 · Raccordement de tête de câble · 48 FO · 19.5 · Raccordement de tête de câble · 36 FO | D37: 240 | E37: =D37/MinParPoint -> 16 | F37: =COUNTIF(Prestations!$F$5:$F$256,A37) -> 3
A38: Tête de câble 96 à 144 FO | B38: par tête | C38: 19.1 · Raccordement de tête de câble · 144 FO · 19.2 · Raccordement de tête de câble · 96 FO | D38: 360 | E38: =D38/MinParPoint -> 24 | F38: =COUNTIF(Prestations!$F$5:$F$256,A38) -> 2
A39: Mesure de liaison client | B39: par mesure | C39: 20.1 · Mesure de liaison fibre POP/NRO → client (1 à 36 FO) | D39: 90 | E39: =D39/MinParPoint -> 6 | F39: =COUNTIF(Prestations!$F$5:$F$256,A39) -> 1 | G39: 20.1.
A40: Mesure de liaison BPE à BPE | B40: par mesure | C40: 20.2 · Mesure de liaison BPE à BPE · câble 48 FO · 20.3 · Mesure de liaison BPE à BPE · câble 72 FO · 20.4 · Mesure de liaison BPE à BPE · câble 144 FO | D40: 360 | E40: =D40/MinParPoint -> 24 | F40: =COUNTIF(Prestations!$F$5:$F$256,A40) -> 3 | G40: 20.2 à 20.4.
A41: Mesure réflectométrique | B41: par fibre | C41: 20.5 · Mesures réflectométriques (1 à 2 fibres) | D41: 30 | E41: =D41/MinParPoint -> 2 | F41: =COUNTIF(Prestations!$F$5:$F$256,A41) -> 1
...

Sheet Prestations
A1: PRESTATIONS DU BPU ET LEURS POINTS
A2: Change la famille (colonne F) ou mets un temps à part (colonne H) si besoin. Colonne I : « oui » = intervention de nuit, majorée.
A4: Projet | B4: Contrat / réseau | C4: Code BPU | D4: Prestation | E4: Unité | F4: Famille | G4: Temps famille (min) | H4: Temps à part (min) | I4: Nuit (HNO) | J4: Temps retenu (min) | K4: Points
A5: AXIONE | B5: RHD57 | C5: MC-T1 | D5: RHD57 · Heure technicien HO · intervention immédiate | E5: Forfait par heure | F5: Heure de technicien | G5: =IFERROR(INDEX(Familles!$D$5:$D$56,MATCH(F5,Familles!$A$5:$A$56,0)),"") -> 60 | J5: =IF(AND(H5="",G5=""),"",IF(H5<>"",H5,G5)*IF(I5="oui",1+MajHNO,1)) -> 60 | K5: =IF(J5="","",J5/MinParPoint) -> 4
A6: AXIONE | B6: RHD57 | C6: MC-T2 | D6: RHD57 · Heure technicien HO · intervention programmée | E6: Forfait par heure | F6: Heure de technicien | G6: =IFERROR(INDEX(Familles!$D$5:$D$56,MATCH(F6,Familles!$A$5:$A$56,0)),"") -> 60 | J6: =IF(AND(H6="",G6=""),"",IF(H6<>"",H6,G6)*IF(I6="oui",1+MajHNO,1)) -> 60 | K6: =IF(J6="","",J6/MinParPoint) -> 4
A7: AXIONE | B7: RHD57 | C7: MC-T3 | D7: RHD57 · Heure technicien HNO | E7: Forfait par heure | F7: Heure de technicien | G7: =IFERROR(INDEX(Familles!$D$5:$D$56,MATCH(F7,Familles!$A$5:$A$56,0)),"") -> 60 | I7: oui | J7: =IF(AND(H7="",G7=""),"",IF(H7<>"",H7,G7)*IF(I7="oui",1+MajHNO,1)) -> 75 | K7: =IF(J7="","",J7/MinParPoint) -> 5
A8: AXIONE | B8: RHD57 | C8: MC-T4 | D8: RHD57 · 2 techniciens + nacelle ≤ 16 m · HO | E8: Forfait par heure | F8: Heure de technicien | G8: =IFERROR(INDEX(Familles!$D$5:$D$56,MATCH(F8,Familles!$A$5:$A$56,0)),"") -> 60 | J8: =IF(AND(H8="",G8=""),"",IF(H8<>"",H8,G8)*IF(I8="oui",1+MajHNO,1)) -> 60 | K8: =IF(J8="","",J8/MinParPoint) -> 4
A9: AXIONE | B9: RHD57 | C9: MC-T5 | D9: RHD57 · 2 techniciens + nacelle ≤ 16 m · HNO | E9: Forfait par heure | F9: Heure de technicien | G9: =IFERROR(INDEX(Familles!$D$5:$D$56,MATCH(F9,Familles!$A$5:$A$56,0)),"") -> 60 | I9: oui | J9: =IF(AND(H9="",G9=""),"",IF(H9<>"",H9,G9)*IF(I9="oui",1+MajHNO,1)) -> 75 | K9: =IF(J9="","",J9/MinParPoint) -> 5
A10: AXIONE | B10: RHD57 | C10: MC-T6 | D10: RHD57 · Nacelle exceptionnelle > 16 m (par mètre) | E10: Par mètre (hauteur nacelle) | F10: Sans temps (matériel, plus-value) | G10: =IFERROR(INDEX(Familles!$D$5:$D$56,MATCH(F10,Familles!$A$5:$A$56,0)),"") -> 0 | J10: =IF(AND(H10="",G10=""),"",IF(H10<>"",H10,G10)*IF(I10="oui",1+MajHNO,1)) -> 0 | K10: =IF(J10="","",J10/MinParPoint) -> 0
A11: AXIONE | B11: CITY FAST | C11: CF-N1-URG-HO | D11: City Fast N1 Site (PM, DME) · Urgente 4h · HO 7h-19h | E11: À l'intervention (prix STT) | F11: City Fast N1 · site (PM, DME) | G11: =IFERROR(INDEX(Familles!$D$5:$D$56,MATCH(F11,Familles!$A$5:$A$56,0)),"") -> 180 | J11: =IF(AND(H11="",G11=""),"",IF(H11<>"",H11,G11)*IF(I11="oui",1+MajHNO,1)) -> 180 | K11: =IF(J11="","",J11/MinParPoint) -> 12
A12: AXIONE | B12: CITY FAST | C12: CF-N1-URG-HNO | D12: City Fast N1 Site (PM, DME) · Urgente 4h · HNO 19h-7h | E12: À l'intervention (prix STT) | F12: City Fast N1 · site (PM, DME) | G12: =IFERROR(INDEX(Familles!$D$5:$D$56,MATCH(F12,Familles!$A$5:$A$56,0)),"") -> 180 | I12: oui | J12: =IF(AND(H12="",G12=""),"",IF(H12<>"",H12,G12)*IF(I12="oui",1+MajHNO,1)) -> 225 | K12: =IF(J12="","",J12/MinParPoint) -> 15
A13: AXIONE | B13: CITY FAST | C13: CF-N1-STDPLUS | D13: City Fast N1 Site (PM, DME) · Standard Plus 24h · HO 7h-19h | E13: À l'intervention (prix STT) | F13: City Fast N1 · site (PM, DME) | G13: =IFERROR(INDEX(Familles!$D$5:$D$56,MATCH(F13,Familles!$A$5:$A$56,0)),"") -> 180 | J13: =IF(AND(H13="",G13=""),"",IF(H13<>"",H13,G13)*IF(I13="oui",1+MajHNO,1)) -> 180 | K13: =IF(J13="","",J13/MinParPoint) -> 12
A14: AXIONE | B14: CITY FAST | C14: CF-N1-STD | D14: City Fast N1 Site (PM, DME) · Standard 5j/7 · HO 7h-19h | E14: À l'intervention (prix STT) | F14: City Fast N1 · site (PM, DME) | G14: =IFERROR(INDEX(Familles!$D$5:$D$56,MATCH(F14,Familles!$A$5:$A$56,0)),"") -> 180 | J14: =IF(AND(H14="",G14=""),"",IF(H14<>"",H14,G14)*IF(I14="oui",1+MajHNO,1)) -> 180 | K14: =IF(J14="","",J14/MinParPoint) -> 12
A15: AXIONE | B15: CITY FAST | C15: CF-N2-URG-HO | D15: City Fast N2 Extrémité câble en chambre (BPE) · Urgente 4h · HO 7h-19h | E15: À l'intervention (prix STT) | F15: City Fast N2 · BPE en chambre | G15: =IFERROR(INDEX(Familles!$D$5:$D$56,MATCH(F15,Familles!$A$5:$A$56,0)),"") -> 240 | J15: =IF(AND(H15="",G15=""),"",IF(H15<>"",H15,G15)*IF(I15="oui",1+MajHNO,1)) -> 240 | K15: =IF(J15="","",J15/MinParPoint) -> 16
A16: AXIONE | B16: CITY FAST | C16: CF-N2-URG-HNO | D16: City Fast N2 Extrémité câble en chambre (BPE) · Urgente 4h · HNO 19h-7h | E16: À l'intervention (prix STT) | F16: City Fast N2 · BPE en chambre | G16: =IFERROR(INDEX(Familles!$D$5:$D$56,MATCH(F16,Familles!$A$5:$A$56,0)),"") -> 240 | I16: oui | J16: =IF(AND(H16="",G16=""),"",IF(H16<>"",H16,G16)*IF(I16="oui",1+MajHNO,1)) -> 300 | K16: =IF(J16="","",J16/MinParPoint) -> 20
A17: AXIONE | B17: CITY FAST | C17: CF-N2-STDPLUS | D17: City Fast N2 Extrémité câble en chambre (BPE) · Standard Plus 24h · HO 7h-19h | E17: À l'intervention (prix STT) | F17: City Fast N2 · BPE en chambre | G17: =IFERROR(INDEX(Familles!$D$5:$D$56,MATCH(F17,Familles!$A$5:$A$56,0)),"") -> 240 | J17: =IF(AND(H17="",G17=""),"",IF(H17<>"",H17,G17)*IF(I17="oui",1+MajHNO,1)) -> 240 | K17: =IF(J17="","",J17/MinParPoint) -> 16
A18: AXIONE | B18: CITY FAST | C18: CF-N2-STD | D18: City Fast N2 Extrémité câble en chambre (BPE) · Standard 5j/7 · HO 7h-19h | E18: À l'intervention (prix STT) | F18: City Fast N2 · BPE en chambre | G18: =IFERROR(INDEX(Familles!$D$5:$D$56,MATCH(F18,Familles!$A$5:$A$56,0)),"") -> 240 | J18: =IF(AND(H18="",G18=""),"",IF(H18<>"",H18,G18)*IF(I18="oui",1+MajHNO,1)) -> 240 | K18: =IF(J18="","",J18/MinParPoint) -> 16
A19: AXIONE | B19: CITY FAST | C19: CF-N3-URG-HO | D19: City Fast N3 Câble en conduite (tirage) · Urgente 4h · HO 7h-19h | E19: À l'intervention (prix STT) | F19: City Fast N3 · câble en conduite | G19: =IFERROR(INDEX(Familles!$D$5:$D$56,MATCH(F19,Familles!$A$5:$A$56,0)),"") -> 360 | J19: =IF(AND(H19="",G19=""),"",IF(H19<>"",H19,G19)*IF(I19="oui",1+MajHNO,1)) -> 360 | K19: =IF(J19="","",J19/MinParPoint) -> 24
A20: AXIONE | B20: CITY FAST | C20: CF-N3-URG-HNO | D20: City Fast N3 Câble en conduite (tirage) · Urgente 4h · HNO 19h-7h | E20: À l'intervention (prix STT) | F20: City Fast N3 · câble en conduite | G20: =IFERROR(INDEX(Familles!$D$5:$D$56,MATCH(F20,Familles!$A$5:$A$56,0)),"") -> 360 | I20: oui | J20: =IF(AND(H20="",G20=""),"",IF(H20<>"",H20,G20)*IF(I20="oui",1+MajHNO,1)) -> 450 | K20: =IF(J20="","",J20/MinParPoint) -> 30
A21: AXIONE | B21: CITY FAST | C21: CF-N3-STDPLUS | D21: City Fast N3 Câble en conduite (tirage) · Standard Plus 24h · HO 7h-19h | E21: À l'intervention (prix STT) | F21: City Fast N3 · câble en conduite | G21: =IFERROR(INDEX(Familles!$D$5:$D$56,MATCH(F21,Familles!$A$5:$A$56,0)),"") -> 360 | J21: =IF(AND(H21="",G21=""),"",IF(H21<>"",H21,G21)*IF(I21="oui",1+MajHNO,1)) -> 360 | K21: =IF(J21="","",J21/MinParPoint) -> 24
A22: AXIONE | B22: CITY FAST | C22: CF-N3-STD | D22: City Fast N3 Câble en conduite (tirage) · Standard 5j/7 · HO 7h-19h | E22: À l'intervention (prix STT) | F22: City Fast N3 · câble en conduite | G22: =IFERROR(INDEX(Familles!$D$5:$D$56,MATCH(F22,Familles!$A$5:$A$56,0)),"") -> 360 | J22: =IF(AND(H22="",G22=""),"",IF(H22<>"",H22,G22)*IF(I22="oui",1+MajHNO,1)) -> 360 | K22: =IF(J22="","",J22/MinParPoint) -> 24
A23: COVAGE | C23: COVAGE-TICKET | D23: Ticket | E23: Le ticket | F23: Ticket intervention | G23: =IFERROR(INDEX(Familles!$D$5:$D$56,MATCH(F23,Familles!$A$5:$A$56,0)),"") -> 120 | J23: =IF(AND(H23="",G23=""),"",IF(H23<>"",H23,G23)*IF(I23="oui",1+MajHNO,1)) -> 120 | K23: =IF(J23="","",J23/MinParPoint) -> 8
A24: ALTITUDE | C24: ALTITUDE-TICKET | D24: Ticket | E24: Le ticket | F24: Ticket intervention | G24: =IFERROR(INDEX(Familles!$D$5:$D$56,MATCH(F24,Familles!$A$5:$A$56,0)),"") -> 120 | J24: =IF(AND(H24="",G24=""),"",IF(H24<>"",H24,G24)*IF(I24="oui",1+MajHNO,1)) -> 120 | K24: =IF(J24="","",J24/MinParPoint) -> 8
A25: ALTITUDE | B25: COVAGE · hors BPU | C25: ALTITUDE-MALF-AERIEN | D25: Malfaçon aérien | E25: Le ticket | F25: Malfaçon aérien | G25: =IFERROR(INDEX(Familles!$D$5:$D$56,MATCH(F25,Familles!$A$5:$A$56,0)),"") -> 150 | J25: =IF(AND(H25="",G25=""),"",IF(H25<>"",H25,G25)*IF(I25="oui",1+MajHNO,1)) -> 150 | K25: =IF(J25="","",J25/MinParPoint) -> 10
A26: ALTITUDE | B26: COVAGE · hors BPU | C26: ALTITUDE-MALF-SOUT | D26: Malfaçon souterrain | E26: Le ticket | F26: Malfaçon souterrain | G26: =IFERROR(INDEX(Familles!$D$5:$D$56,MATCH(F26,Familles!$A$5:$A$56,0)),"") -> 90 | J26: =IF(AND(H26="",G26=""),"",IF(H26<>"",H26,G26)*IF(I26="oui",1+MajHNO,1)) -> 90 | K26: =IF(J26="","",J26/MinParPoint) -> 6
A27: CELESTE | B27: SAV | C27: SAV-F0 | D27: SAV F0 · Niveau 0 | E27: U (forfait) | F27: SAV niveau 0 | G27: =IFERROR(INDEX(Familles!$D$5:$D$56,MATCH(F27,Familles!$A$5:$A$56,0)),"") -> 90 | J27: =IF(AND(H27="",G27=""),"",IF(H27<>"",H27,G27)*IF(I27="oui",1+MajHNO,1)) -> 90 | K27: =IF(J27="","",J27/MinParPoint) -> 6
A28: CELESTE | B28: SAV | C28: SAV-F0-HNO | D28: SAV F0 · Niveau 0 en HNO | E28: U (forfait) | F28: SAV niveau 0 | G28: =IFERROR(INDEX(Familles!$D$5:$D$56,MATCH(F28,Familles!$A$5:$A$56,0)),"") -> 90 | I28: oui | J28: =IF(AND(H28="",G28=""),"",IF(H28<>"",H28,G28)*IF(I28="oui",1+MajHNO,1)) -> 112.5 | K28: =IF(J28="","",J28/MinParPoint) -> 7.5
A29: CELESTE | B29: SAV | C29: SAV-F1 | D29: SAV F1 · Niveau 1 (inclut F0) | E29: U (forfait) | F29: SAV niveau 1 | G29: =IFERROR(INDEX(Familles!$D$5:$D$56,MATCH(F29,Familles!$A$5:$A$56,0)),"") -> 180 | J29: =IF(AND(H29="",G29=""),"",IF(H29<>"",H29,G29)*IF(I29="oui",1+MajHNO,1)) -> 180 | K29: =IF(J29="","",J29/MinParPoint) -> 12
A30: CELESTE | B30: SAV | C30: SAV-F1-HNO | D30: SAV F1 · Niveau 1 en HNO (inclut F0) | E30: U (forfait) | F30: SAV niveau 1 | G30: =IFERROR(INDEX(Familles!$D$5:$D$56,MATCH(F30,Familles!$A$5:$A$56,0)),"") -> 180 | I30: oui | J30: =IF(AND(H30="",G30=""),"",IF(H30<>"",H30,G30)*IF(I30="oui",1+MajHNO,1)) -> 225 | K30: =IF(J30="","",J30/MinParPoint) -> 15
A31: CELESTE | B31: SAV | C31: SAV-F2 | D31: SAV F2 · Niveau 2 (inclut F1) | E31: U (forfait) | F31: SAV niveau 2 | G31: =IFERROR(INDEX(Familles!$D$5:$D$56,MATCH(F31,Familles!$A$5:$A$56,0)),"") -> 300 | J31: =IF(AND(H31="",G31=""),"",IF(H31<>"",H31,G31)*IF(I31="oui",1+MajHNO,1)) -> 300 | K31: =IF(J31="","",J31/MinParPoint) -> 20
A32: CELESTE | B32: SAV | C32: SAV-F2-HNO | D32: SAV F2 · Niveau 2 en HNO (inclut F1) | E32: U (forfait) | F32: SAV niveau 2 | G32: =IFERROR(INDEX(Familles!$D$5:$D$56,MATCH(F32,Familles!$A$5:$A$56,0)),"") -> 300 | I32: oui | J32: =IF(AND(H32="",G32=""),"",IF(H32<>"",H32,G32)*IF(I32="oui",1+MajHNO,1)) -> 375 | K32: =IF(J32="","",J32/MinParPoint) -> 25
A33: IELO | C33: IELO-TICKET | D33: Ticket | E33: Le ticket | F33: Ticket intervention | G33: =IFERROR(INDEX(Familles!$D$5:$D$56,MATCH(F33,Familles!$A$5:$A$56,0)),"") -> 120 | J33: =IF(AND(H33="",G33=""),"",IF(H33<>"",H33,G33)*IF(I33="oui",1+MajHNO,1)) -> 120 | K33: =IF(J33="","",J33/MinParPoint) -> 8
A34: FREE | C34: FREE-TICKET | D34: Ticket | E34: Le ticket | F34: Ticket intervention | G34: =IFERROR(INDEX(Familles!$D$5:$D$56,MATCH(F34,Familles!$A$5:$A$56,0)),"") -> 120 | J34: =IF(AND(H34="",G34=""),"",IF(H34<>"",H34,G34)*IF(I34="oui",1+MajHNO,1)) -> 120 | K34: =IF(J34="","",J34/MinParPoint) -> 8
A35: LOSANGE | C35: LOSANGE-TICKET | D35: Ticket | E35: Le ticket | F35: Ticket intervention | G35: =IFERROR(INDEX(Familles!$D$5:$D$56,MATCH(F35,Familles!$A$5:$A$56,0)),"") -> 120 | J35: =IF(AND(H35="",G35=""),"",IF(H35<>"",H35,G35)*IF(I35="oui",1+MajHNO,1)) -> 120 | K35: =IF(J35="","",J35/MinParPoint) -> 8
A36: LOSANGE | B36: COVAGE · hors BPU | C36: LOSANGE-MALF-AERIEN | D36: Malfaçon aérien | E36: Le ticket | F36: Malfaçon aérien | G36: =IFERROR(INDEX(Familles!$D$5:$D$56,MATCH(F36,Familles!$A$5:$A$56,0)),"") -> 150 | J36: =IF(AND(H36="",G36=""),"",IF(H36<>"",H36,G36)*IF(I36="oui",1+MajHNO,1)) -> 150 | K36: =IF(J36="","",J36/MinParPoint) -> 10
A37: LOSANGE | B37: COVAGE · hors BPU | C37: LOSANGE-MALF-SOUT | D37: Malfaçon souterrain | E37: Le ticket | F37: Malfaçon souterrain | G37: =IFERROR(INDEX(Familles!$D$5:$D$56,MATCH(F37,Familles!$A$5:$A$56,0)),"") -> 90 | J37: =IF(AND(H37="",G37=""),"",IF(H37<>"",H37,G37)*IF(I37="oui",1+MajHNO,1)) -> 90 | K37: =IF(J37="","",J37/MinParPoint) -> 6
A38: CONGÉS | C38: CONGES-JOUR | D38: Journée de congés | E38: La journée | F38: Absence (non comptée) | G38: =IFERROR(INDEX(Familles!$D$5:$D$56,MATCH(F38,Familles!$A$5:$A$56,0)),"") -> 0 | J38: =IF(AND(H38="",G38=""),"",IF(H38<>"",H38,G38)*IF(I38="oui",1+MajHNO,1)) -> 0 | K38: =IF(J38="","",J38/MinParPoint) -> 0
A39: ABSENCE | C39: ABSENCE-JOUR | D39: Journée d'absence | E39: La journée | F39: Absence (non comptée) | G39: =IFERROR(INDEX(Familles!$D$5:$D$56,MATCH(F39,Familles!$A$5:$A$56,0)),"") -> 0 | J39: =IF(AND(H39="",G39=""),"",IF(H39<>"",H39,G39)*IF(I39="oui",1+MajHNO,1)) -> 0 | K39: =IF(J39="","",J39/MinParPoint) -> 0
A40: COVAGE | B40: Super forfaits | C40: COV-SF-Z100 | D40: Super forfait · Z100 (NEW) | E40: Forfait | F40: Raccordement entreprise avec extension (Z50 à Z200) | G40: =IFERROR(INDEX(Familles!$D$5:$D$56,MATCH(F40,Familles!$A$5:$A$56,0)),"") -> 600 | J40: =IF(AND(H40="",G40=""),"",IF(H40<>"",H40,G40)*IF(I40="oui",1+MajHNO,1)) -> 600 | K40: =IF(J40="","",J40/MinParPoint) -> 40
A41: COVAGE | B41: Super forfaits | C41: COV-SF-Z200 | D41: Super forfait · Z200 (NEW) | E41: Forfait | F41: Raccordement entreprise avec extension (Z50 à Z200) | G41: =IFERROR(INDEX(Familles!$D$5:$D$56,MATCH(F41,Familles!$A$5:$A$56,0)),"") -> 600 | J41: =IF(AND(H41="",G41=""),"",IF(H41<>"",H41,G41)*IF(I41="oui",1+MajHNO,1)) -> 600 | K41: =IF(J41="","",J41/MinParPoint) -> 40
...

Sheet Exemple
A1: EXEMPLE : DEUX JOURNÉES COMPARÉES AVEC LES POINTS
A2: Change les codes (colonne B) et les quantités (colonne D) pour tester. Les points se calculent avec le barème.
A4: Technicien | B4: Code BPU | C4: Prestation | D4: Quantité | E4: Points / unité | F4: Points
A5: Technicien A | B5: COVAGE-TICKET | C5: =IF(B5="","",IFERROR(INDEX(Prestations!$D$5:$D$256,MATCH(B5,Prestations!$C$5:$C$256,0)),"Code inconnu")) -> Ticket | D5: 3 | E5: =IF(B5="","",IFERROR(INDEX(Prestations!$K$5:$K$256,MATCH(B5,Prestations!$C$5:$C$256,0)),0)) -> 8 | F5: =IF(B5="","",N(D5)*E5) -> 24
A6: Technicien B | B6: ALTITUDE-MALF-AERIEN | C6: =IF(B6="","",IFERROR(INDEX(Prestations!$D$5:$D$256,MATCH(B6,Prestations!$C$5:$C$256,0)),"Code inconnu")) -> Malfaçon aérien | D6: 2 | E6: =IF(B6="","",IFERROR(INDEX(Prestations!$K$5:$K$256,MATCH(B6,Prestations!$C$5:$C$256,0)),0)) -> 10 | F6: =IF(B6="","",N(D6)*E6) -> 20
A7: Technicien B | B7: LOSANGE-MALF-SOUT | C7: =IF(B7="","",IFERROR(INDEX(Prestations!$D$5:$D$256,MATCH(B7,Prestations!$C$5:$C$256,0)),"Code inconnu")) -> Malfaçon souterrain | D7: 1 | E7: =IF(B7="","",IFERROR(INDEX(Prestations!$K$5:$K$256,MATCH(B7,Prestations!$C$5:$C$256,0)),0)) -> 6 | F7: =IF(B7="","",N(D7)*E7) -> 6
C8: =IF(B8="","",IFERROR(INDEX(Prestations!$D$5:$D$256,MATCH(B8,Prestations!$C$5:$C$256,0)),"Code inconnu")) | E8: =IF(B8="","",IFERROR(INDEX(Prestations!$K$5:$K$256,MATCH(B8,Prestations!$C$5:$C$256,0)),0)) | F8: =IF(B8="","",N(D8)*E8)
C9: =IF(B9="","",IFERROR(INDEX(Prestations!$D$5:$D$256,MATCH(B9,Prestations!$C$5:$C$256,0)),"Code inconnu")) | E9: =IF(B9="","",IFERROR(INDEX(Prestations!$K$5:$K$256,MATCH(B9,Prestations!$C$5:$C$256,0)),0)) | F9: =IF(B9="","",N(D9)*E9)
C10: =IF(B10="","",IFERROR(INDEX(Prestations!$D$5:$D$256,MATCH(B10,Prestations!$C$5:$C$256,0)),"Code inconnu")) | E10: =IF(B10="","",IFERROR(INDEX(Prestations!$K$5:$K$256,MATCH(B10,Prestations!$C$5:$C$256,0)),0)) | F10: =IF(B10="","",N(D10)*E10)
A12: Résultat de la journée
A13: Technicien | B13: Points de la journée | C13: Points attendus | D13: Taux
A14: Technicien A | B14: =SUMIFS($F$5:$F$10,$A$5:$A$10,A14) -> 24 | C14: =PointsJour -> 28 | D14: =IF(C14>0,B14/C14,"") -> 0.85714286
A15: Technicien B | B15: =SUMIFS($F$5:$F$10,$A$5:$A$10,A15) -> 26 | C15: =PointsJour -> 28 | D15: =IF(C15>0,B15/C15,"") -> 0.92857143
A17: A a fait 3 tickets COVAGE, bien payés. B a fait 3 malfaçons, mal payées mais longues (dont 2 en hauteur). En euros, A rapporte plus de deux fois plus que B et passerait pour le meilleur.
A18: Avec les points, B a en réalité travaillé plus longtemps que A : chacun est jugé sur son temps de travail, pas sur le tarif du client.
A19: Lignes 8 à 10 libres : ajoute un technicien, un code BPU et une quantité pour tester d'autres journées.
