Workbook

Sheet Mode d'emploi
A1: FEUILLE DE PROD : CHAQUE TECHNICIEN JUGÉ SUR SON TRAVAIL, PAS SUR LE PRIX DU MARCHÉ
A3: LE PROBLÈME
A4: Un ticket rapporte 400 € chez COVAGE et 207 € chez LOSANGE, une heure AXIONE environ 35 € (prix du BPU). Compter la production en euros, c'est juger le technicien sur le marché où tu l'envoies.
A6: LA SOLUTION : COMPTER EN JOURNÉES
A7: Pour chaque marché, tu dis combien un technicien en fait dans une journée normale (onglet Règles) : 4 tickets LOSANGE = 1 journée, 2 tickets COVAGE = 1 journée, 7 heures AXIONE = 1 journée.
A8: Taux de production = journées produites ÷ jours travaillés. 100 % = une journée normale chaque jour travaillé, quel que soit le marché.
A9: Les euros ne disparaissent pas : le CA est toujours calculé, par technicien et par marché, pour toi.
A11: CE QUE TU AS À FAIRE
A12: 1. Onglet « Règles » : vérifie les nombres des cases jaunes (combien dans une journée normale). FREE est à compléter.
A13: 2. Onglet « Saisies » : dans le Google Sheet, copie l'onglet Saisies de la ligne 2 jusqu'à la fin (colonnes A à N) et colle en A2. Tu peux aussi taper une ligne : date, technicien, projet, quantité et code BPU (liste en colonne G).
A14: 3. Onglet « Production » : choisis les dates (du… au…). Jours travaillés, journées produites, taux, classement et CA se calculent seuls.
A16: Cases jaunes, chiffres en bleu = à remplir. Le reste est calculé : ne pas modifier.
... A24: • Onglet « Exemple » : quatre techniciens, une journée normale chacun sur quatre marchés, pour voir la différence avec les euros.

Sheet Production
A1: PRODUCTION DES TECHNICIENS
A3: Du | B3: 46296 | C3: =COUNTIF(Saisies!$V$2:$V$100000,"?*")&" ligne(s) à vérifier dans l'onglet Saisies (colonne V)" -> 0 ligne(s) à vérifier dans l'onglet Saisies (colonne V)
A4: Au | B4: 46326 | C4: Choisis les dates : une semaine, un mois, l'année…
A6: Technicien | B6: Jours travaillés | C6: Journées produites | D6: Taux de production | E6: Classement | F6: CA (€) | G6: Classement au CA (ancienne méthode) | H6: Lignes à vérifier
A7: ROMAIN LUCAS | B7: =IF($A7="","",SUMIFS(Saisies!$U:$U,Saisies!$B:$B,$A7,Saisies!$A:$A,">="&$B$3,Saisies!$A:$A,"<="&$B$4)) -> 0 | C7: =IF($A7="","",SUMIFS(Saisies!$S:$S,Saisies!$B:$B,$A7,Saisies!$A:$A,">="&$B$3,Saisies!$A:$A,"<="&$B$4)) -> 0 | D7: =IF(OR($A7="",N(B7)=0),"",C7/B7) | E7: =IF(D7="","",RANK(D7,$D$7:$D$21)) | F7: =IF($A7="","",SUMIFS(Saisies!$R:$R,Saisies!$B:$B,$A7,Saisies!$A:$A,">="&$B$3,Saisies!$A:$A,"<="&$B$4)) -> 0 | G7: =IF(OR($A7="",N(F7)=0),"",RANK(F7,$F$7:$F$21)) | H7: =IF($A7="","",COUNTIFS(Saisies!$B:$B,$A7,Saisies!$A:$A,">="&$B$3,Saisies!$A:$A,"<="&$B$4,Saisies!$V:$V,"?*")) -> 0
A8: HUGO POUILLARD | B8: =IF($A8="","",SUMIFS(Saisies!$U:$U,Saisies!$B:$B,$A8,Saisies!$A:$A,">="&$B$3,Saisies!$A:$A,"<="&$B$4)) -> 0 | C8: =IF($A8="","",SUMIFS(Saisies!$S:$S,Saisies!$B:$B,$A8,Saisies!$A:$A,">="&$B$3,Saisies!$A:$A,"<="&$B$4)) -> 0 | D8: =IF(OR($A8="",N(B8)=0),"",C8/B8) | E8: =IF(D8="","",RANK(D8,$D$7:$D$21)) | F8: =IF($A8="","",SUMIFS(Saisies!$R:$R,Saisies!$B:$B,$A8,Saisies!$A:$A,">="&$B$3,Saisies!$A:$A,"<="&$B$4)) -> 0 | G8: =IF(OR($A8="",N(F8)=0),"",RANK(F8,$F$7:$F$21)) | H8: =IF($A8="","",COUNTIFS(Saisies!$B:$B,$A8,Saisies!$A:$A,">="&$B$3,Saisies!$A:$A,"<="&$B$4,Saisies!$V:$V,"?*")) -> 0
A9: FLORIAN BAJONI | B9: =IF($A9="","",SUMIFS(Saisies!$U:$U,Saisies!$B:$B,$A9,Saisies!$A:$A,">="&$B$3,Saisies!$A:$A,"<="&$B$4)) -> 0 | C9: =IF($A9="","",SUMIFS(Saisies!$S:$S,Saisies!$B:$B,$A9,Saisies!$A:$A,">="&$B$3,Saisies!$A:$A,"<="&$B$4)) -> 0 | D9: =IF(OR($A9="",N(B9)=0),"",C9/B9) | E9: =IF(D9="","",RANK(D9,$D$7:$D$21)) | F9: =IF($A9="","",SUMIFS(Saisies!$R:$R,Saisies!$B:$B,$A9,Saisies!$A:$A,">="&$B$3,Saisies!$A:$A,"<="&$B$4)) -> 0 | G9: =IF(OR($A9="",N(F9)=0),"",RANK(F9,$F$7:$F$21)) | H9: =IF($A9="","",COUNTIFS(Saisies!$B:$B,$A9,Saisies!$A:$A,">="&$B$3,Saisies!$A:$A,"<="&$B$4,Saisies!$V:$V,"?*")) -> 0
A10: ROMAIN VALLON | B10: =IF($A10="","",SUMIFS(Saisies!$U:$U,Saisies!$B:$B,$A10,Saisies!$A:$A,">="&$B$3,Saisies!$A:$A,"<="&$B$4)) -> 0 | C10: =IF($A10="","",SUMIFS(Saisies!$S:$S,Saisies!$B:$B,$A10,Saisies!$A:$A,">="&$B$3,Saisies!$A:$A,"<="&$B$4)) -> 0 | D10: =IF(OR($A10="",N(B10)=0),"",C10/B10) | E10: =IF(D10="","",RANK(D10,$D$7:$D$21)) | F10: =IF($A10="","",SUMIFS(Saisies!$R:$R,Saisies!$B:$B,$A10,Saisies!$A:$A,">="&$B$3,Saisies!$A:$A,"<="&$B$4)) -> 0 | G10: =IF(OR($A10="",N(F10)=0),"",RANK(F10,$F$7:$F$21)) | H10: =IF($A10="","",COUNTIFS(Saisies!$B:$B,$A10,Saisies!$A:$A,">="&$B$3,Saisies!$A:$A,"<="&$B$4,Saisies!$V:$V,"?*")) -> 0
A11: ERIC PATRYARCHA | B11: =IF($A11="","",SUMIFS(Saisies!$U:$U,Saisies!$B:$B,$A11,Saisies!$A:$A,">="&$B$3,Saisies!$A:$A,"<="&$B$4)) -> 0 | C11: =IF($A11="","",SUMIFS(Saisies!$S:$S,Saisies!$B:$B,$A11,Saisies!$A:$A,">="&$B$3,Saisies!$A:$A,"<="&$B$4)) -> 0 | D11: =IF(OR($A11="",N(B11)=0),"",C11/B11) | E11: =IF(D11="","",RANK(D11,$D$7:$D$21)) | F11: =IF($A11="","",SUMIFS(Saisies!$R:$R,Saisies!$B:$B,$A11,Saisies!$A:$A,">="&$B$3,Saisies!$A:$A,"<="&$B$4)) -> 0 | G11: =IF(OR($A11="",N(F11)=0),"",RANK(F11,$F$7:$F$21)) | H11: =IF($A11="","",COUNTIFS(Saisies!$B:$B,$A11,Saisies!$A:$A,">="&$B$3,Saisies!$A:$A,"<="&$B$4,Saisies!$V:$V,"?*")) -> 0
A12: LOIC GERARD | B12: =IF($A12="","",SUMIFS(Saisies!$U:$U,Saisies!$B:$B,$A12,Saisies!$A:$A,">="&$B$3,Saisies!$A:$A,"<="&$B$4)) -> 0 | C12: =IF($A12="","",SUMIFS(Saisies!$S:$S,Saisies!$B:$B,$A12,Saisies!$A:$A,">="&$B$3,Saisies!$A:$A,"<="&$B$4)) -> 0 | D12: =IF(OR($A12="",N(B12)=0),"",C12/B12) | E12: =IF(D12="","",RANK(D12,$D$7:$D$21)) | F12: =IF($A12="","",SUMIFS(Saisies!$R:$R,Saisies!$B:$B,$A12,Saisies!$A:$A,">="&$B$3,Saisies!$A:$A,"<="&$B$4)) -> 0 | G12: =IF(OR($A12="",N(F12)=0),"",RANK(F12,$F$7:$F$21)) | H12: =IF($A12="","",COUNTIFS(Saisies!$B:$B,$A12,Saisies!$A:$A,">="&$B$3,Saisies!$A:$A,"<="&$B$4,Saisies!$V:$V,"?*")) -> 0
B13: =IF($A13="","",SUMIFS(Saisies!$U:$U,Saisies!$B:$B,$A13,Saisies!$A:$A,">="&$B$3,Saisies!$A:$A,"<="&$B$4)) | C13: =IF($A13="","",SUMIFS(Saisies!$S:$S,Saisies!$B:$B,$A13,Saisies!$A:$A,">="&$B$3,Saisies!$A:$A,"<="&$B$4)) | D13: =IF(OR($A13="",N(B13)=0),"",C13/B13) | E13: =IF(D13="","",RANK(D13,$D$7:$D$21)) | F13: =IF($A13="","",SUMIFS(Saisies!$R:$R,Saisies!$B:$B,$A13,Saisies!$A:$A,">="&$B$3,Saisies!$A:$A,"<="&$B$4)) | G13: =IF(OR($A13="",N(F13)=0),"",RANK(F13,$F$7:$F$21)) | H13: =IF($A13="","",COUNTIFS(Saisies!$B:$B,$A13,Saisies!$A:$A,">="&$B$3,Saisies!$A:$A,"<="&$B$4,Saisies!$V:$V,"?*"))
B14: =IF($A14="","",SUMIFS(Saisies!$U:$U,Saisies!$B:$B,$A14,Saisies!$A:$A,">="&$B$3,Saisies!$A:$A,"<="&$B$4)) | C14: =IF($A14="","",SUMIFS(Saisies!$S:$S,Saisies!$B:$B,$A14,Saisies!$A:$A,">="&$B$3,Saisies!$A:$A,"<="&$B$4)) | D14: =IF(OR($A14="",N(B14)=0),"",C14/B14) | E14: =IF(D14="","",RANK(D14,$D$7:$D$21)) | F14: =IF($A14="","",SUMIFS(Saisies!$R:$R,Saisies!$B:$B,$A14,Saisies!$A:$A,">="&$B$3,Saisies!$A:$A,"<="&$B$4)) | G14: =IF(OR($A14="",N(F14)=0),"",RANK(F14,$F$7:$F$21)) | H14: =IF($A14="","",COUNTIFS(Saisies!$B:$B,$A14,Saisies!$A:$A,">="&$B$3,Saisies!$A:$A,"<="&$B$4,Saisies!$V:$V,"?*"))
B15: =IF($A15="","",SUMIFS(Saisies!$U:$U,Saisies!$B:$B,$A15,Saisies!$A:$A,">="&$B$3,Saisies!$A:$A,"<="&$B$4)) | C15: =IF($A15="","",SUMIFS(Saisies!$S:$S,Saisies!$B:$B,$A15,Saisies!$A:$A,">="&$B$3,Saisies!$A:$A,"<="&$B$4)) | D15: =IF(OR($A15="",N(B15)=0),"",C15/B15) | E15: =IF(D15="","",RANK(D15,$D$7:$D$21)) | F15: =IF($A15="","",SUMIFS(Saisies!$R:$R,Saisies!$B:$B,$A15,Saisies!$A:$A,">="&$B$3,Saisies!$A:$A,"<="&$B$4)) | G15: =IF(OR($A15="",N(F15)=0),"",RANK(F15,$F$7:$F$21)) | H15: =IF($A15="","",COUNTIFS(Saisies!$B:$B,$A15,Saisies!$A:$A,">="&$B$3,Saisies!$A:$A,"<="&$B$4,Saisies!$V:$V,"?*"))
B16: =IF($A16="","",SUMIFS(Saisies!$U:$U,Saisies!$B:$B,$A16,Saisies!$A:$A,">="&$B$3,Saisies!$A:$A,"<="&$B$4)) | C16: =IF($A16="","",SUMIFS(Saisies!$S:$S,Saisies!$B:$B,$A16,Saisies!$A:$A,">="&$B$3,Saisies!$A:$A,"<="&$B$4)) | D16: =IF(OR($A16="",N(B16)=0),"",C16/B16) | E16: =IF(D16="","",RANK(D16,$D$7:$D$21)) | F16: =IF($A16="","",SUMIFS(Saisies!$R:$R,Saisies!$B:$B,$A16,Saisies!$A:$A,">="&$B$3,Saisies!$A:$A,"<="&$B$4)) | G16: =IF(OR($A16="",N(F16)=0),"",RANK(F16,$F$7:$F$21)) | H16: =IF($A16="","",COUNTIFS(Saisies!$B:$B,$A16,Saisies!$A:$A,">="&$B$3,Saisies!$A:$A,"<="&$B$4,Saisies!$V:$V,"?*"))
B17: =IF($A17="","",SUMIFS(Saisies!$U:$U,Saisies!$B:$B,$A17,Saisies!$A:$A,">="&$B$3,Saisies!$A:$A,"<="&$B$4)) | C17: =IF($A17="","",SUMIFS(Saisies!$S:$S,Saisies!$B:$B,$A17,Saisies!$A:$A,">="&$B$3,Saisies!$A:$A,"<="&$B$4)) | D17: =IF(OR($A17="",N(B17)=0),"",C17/B17) | E17: =IF(D17="","",RANK(D17,$D$7:$D$21)) | F17: =IF($A17="","",SUMIFS(Saisies!$R:$R,Saisies!$B:$B,$A17,Saisies!$A:$A,">="&$B$3,Saisies!$A:$A,"<="&$B$4)) | G17: =IF(OR($A17="",N(F17)=0),"",RANK(F17,$F$7:$F$21)) | H17: =IF($A17="","",COUNTIFS(Saisies!$B:$B,$A17,Saisies!$A:$A,">="&$B$3,Saisies!$A:$A,"<="&$B$4,Saisies!$V:$V,"?*"))
B18: =IF($A18="","",SUMIFS(Saisies!$U:$U,Saisies!$B:$B,$A18,Saisies!$A:$A,">="&$B$3,Saisies!$A:$A,"<="&$B$4)) | C18: =IF($A18="","",SUMIFS(Saisies!$S:$S,Saisies!$B:$B,$A18,Saisies!$A:$A,">="&$B$3,Saisies!$A:$A,"<="&$B$4)) | D18: =IF(OR($A18="",N(B18)=0),"",C18/B18) | E18: =IF(D18="","",RANK(D18,$D$7:$D$21)) | F18: =IF($A18="","",SUMIFS(Saisies!$R:$R,Saisies!$B:$B,$A18,Saisies!$A:$A,">="&$B$3,Saisies!$A:$A,"<="&$B$4)) | G18: =IF(OR($A18="",N(F18)=0),"",RANK(F18,$F$7:$F$21)) | H18: =IF($A18="","",COUNTIFS(Saisies!$B:$B,$A18,Saisies!$A:$A,">="&$B$3,Saisies!$A:$A,"<="&$B$4,Saisies!$V:$V,"?*"))
B19: =IF($A19="","",SUMIFS(Saisies!$U:$U,Saisies!$B:$B,$A19,Saisies!$A:$A,">="&$B$3,Saisies!$A:$A,"<="&$B$4)) | C19: =IF($A19="","",SUMIFS(Saisies!$S:$S,Saisies!$B:$B,$A19,Saisies!$A:$A,">="&$B$3,Saisies!$A:$A,"<="&$B$4)) | D19: =IF(OR($A19="",N(B19)=0),"",C19/B19) | E19: =IF(D19="","",RANK(D19,$D$7:$D$21)) | F19: =IF($A19="","",SUMIFS(Saisies!$R:$R,Saisies!$B:$B,$A19,Saisies!$A:$A,">="&$B$3,Saisies!$A:$A,"<="&$B$4)) | G19: =IF(OR($A19="",N(F19)=0),"",RANK(F19,$F$7:$F$21)) | H19: =IF($A19="","",COUNTIFS(Saisies!$B:$B,$A19,Saisies!$A:$A,">="&$B$3,Saisies!$A:$A,"<="&$B$4,Saisies!$V:$V,"?*"))
B20: =IF($A20="","",SUMIFS(Saisies!$U:$U,Saisies!$B:$B,$A20,Saisies!$A:$A,">="&$B$3,Saisies!$A:$A,"<="&$B$4)) | C20: =IF($A20="","",SUMIFS(Saisies!$S:$S,Saisies!$B:$B,$A20,Saisies!$A:$A,">="&$B$3,Saisies!$A:$A,"<="&$B$4)) | D20: =IF(OR($A20="",N(B20)=0),"",C20/B20) | E20: =IF(D20="","",RANK(D20,$D$7:$D$21)) | F20: =IF($A20="","",SUMIFS(Saisies!$R:$R,Saisies!$B:$B,$A20,Saisies!$A:$A,">="&$B$3,Saisies!$A:$A,"<="&$B$4)) | G20: =IF(OR($A20="",N(F20)=0),"",RANK(F20,$F$7:$F$21)) | H20: =IF($A20="","",COUNTIFS(Saisies!$B:$B,$A20,Saisies!$A:$A,">="&$B$3,Saisies!$A:$A,"<="&$B$4,Saisies!$V:$V,"?*"))
B21: =IF($A21="","",SUMIFS(Saisies!$U:$U,Saisies!$B:$B,$A21,Saisies!$A:$A,">="&$B$3,Saisies!$A:$A,"<="&$B$4)) | C21: =IF($A21="","",SUMIFS(Saisies!$S:$S,Saisies!$B:$B,$A21,Saisies!$A:$A,">="&$B$3,Saisies!$A:$A,"<="&$B$4)) | D21: =IF(OR($A21="",N(B21)=0),"",C21/B21) | E21: =IF(D21="","",RANK(D21,$D$7:$D$21)) | F21: =IF($A21="","",SUMIFS(Saisies!$R:$R,Saisies!$B:$B,$A21,Saisies!$A:$A,">="&$B$3,Saisies!$A:$A,"<="&$B$4)) | G21: =IF(OR($A21="",N(F21)=0),"",RANK(F21,$F$7:$F$21)) | H21: =IF($A21="","",COUNTIFS(Saisies!$B:$B,$A21,Saisies!$A:$A,">="&$B$3,Saisies!$A:$A,"<="&$B$4,Saisies!$V:$V,"?*"))
A22: Total équipe | B22: =SUM(B7:B21) -> 0 | C22: =SUM(C7:C21) -> 0 | D22: =IF(N(B22)=0,"",C22/B22) | F22: =SUM(F7:F21) -> 0 | H22: =SUM(H7:H21) -> 0
A23: Taux 100 % = une journée normale par jour travaillé, quel que soit le marché. Les congés et absences ne comptent pas comme jours travaillés.
A24: « Classement au CA » = l'ancienne façon de compter, en euros, laissée pour comparer.
A26: PAR MARCHÉ, SUR LES MÊMES DATES
A27: Marché | B27: Journées produites | C27: CA (€) | D27: CA pour une journée de travail (€)
A28: AXIONE | B28: =SUMIFS(Saisies!$S:$S,Saisies!$C:$C,$A28,Saisies!$A:$A,">="&$B$3,Saisies!$A:$A,"<="&$B$4) -> 0 | C28: =SUMIFS(Saisies!$R:$R,Saisies!$C:$C,$A28,Saisies!$A:$A,">="&$B$3,Saisies!$A:$A,"<="&$B$4) -> 0 | D28: =IF(N(B28)=0,"",C28/B28)
A29: COVAGE | B29: =SUMIFS(Saisies!$S:$S,Saisies!$C:$C,$A29,Saisies!$A:$A,">="&$B$3,Saisies!$A:$A,"<="&$B$4) -> 0 | C29: =SUMIFS(Saisies!$R:$R,Saisies!$C:$C,$A29,Saisies!$A:$A,">="&$B$3,Saisies!$A:$A,"<="&$B$4) -> 0 | D29: =IF(N(B29)=0,"",C29/B29)
A30: ALTITUDE | B30: =SUMIFS(Saisies!$S:$S,Saisies!$C:$C,$A30,Saisies!$A:$A,">="&$B$3,Saisies!$A:$A,"<="&$B$4) -> 0 | C30: =SUMIFS(Saisies!$R:$R,Saisies!$C:$C,$A30,Saisies!$A:$A,">="&$B$3,Saisies!$A:$A,"<="&$B$4) -> 0 | D30: =IF(N(B30)=0,"",C30/B30)
A31: CELESTE | B31: =SUMIFS(Saisies!$S:$S,Saisies!$C:$C,$A31,Saisies!$A:$A,">="&$B$3,Saisies!$A:$A,"<="&$B$4) -> 0 | C31: =SUMIFS(Saisies!$R:$R,Saisies!$C:$C,$A31,Saisies!$A:$A,">="&$B$3,Saisies!$A:$A,"<="&$B$4) -> 0 | D31: =IF(N(B31)=0,"",C31/B31)
A32: IELO | B32: =SUMIFS(Saisies!$S:$S,Saisies!$C:$C,$A32,Saisies!$A:$A,">="&$B$3,Saisies!$A:$A,"<="&$B$4) -> 0 | C32: =SUMIFS(Saisies!$R:$R,Saisies!$C:$C,$A32,Saisies!$A:$A,">="&$B$3,Saisies!$A:$A,"<="&$B$4) -> 0 | D32: =IF(N(B32)=0,"",C32/B32)
A33: FREE | B33: =SUMIFS(Saisies!$S:$S,Saisies!$C:$C,$A33,Saisies!$A:$A,">="&$B$3,Saisies!$A:$A,"<="&$B$4) -> 0 | C33: =SUMIFS(Saisies!$R:$R,Saisies!$C:$C,$A33,Saisies!$A:$A,">="&$B$3,Saisies!$A:$A,"<="&$B$4) -> 0 | D33: =IF(N(B33)=0,"",C33/B33)
A34: LOSANGE | B34: =SUMIFS(Saisies!$S:$S,Saisies!$C:$C,$A34,Saisies!$A:$A,">="&$B$3,Saisies!$A:$A,"<="&$B$4) -> 0 | C34: =SUMIFS(Saisies!$R:$R,Saisies!$C:$C,$A34,Saisies!$A:$A,">="&$B$3,Saisies!$A:$A,"<="&$B$4) -> 0 | D34: =IF(N(B34)=0,"",C34/B34)
A35: La dernière colonne montre ce que rapporte une journée de travail sur chaque marché : utile pour savoir quels marchés valent le coup.

Sheet Saisies
A1: Date | B1: Technicien | C1: Projet | D1: Prestation (si le projet en a plusieurs) | E1: Quantité (vide = 1) | F1: Désignation | G1: Code BPU | H1: Unité | I1: PU (€) (vide = prix du BPU) | J1: Montant (€) | K1: N° ticket / référence | L1: Commentaire | M1: ID | N1: Saisi le | O1: Catégorie (calculé) | P1: Comment ça compte (calculé) | Q1: PU retenu (€) (calculé) | R1: Montant (€) (calculé) | S1: Journées produites (calculé) | T1: Travail (calculé) | U1: Jour travaillé (calculé) | V1: À vérifier (calculé)
O2: =IF($G2="","",IFERROR(INDEX(Prestations!$F$5:$F$256,MATCH($G2,Prestations!$B$5:$B$256,0)),"?")) | P2: =IF($O2="","",IF($O2="?","?",IFERROR(INDEX(Règles!$C$5:$C$17,MATCH($O2,Règles!$A$5:$A$17,0)),"?"))) | Q2: =IF($G2="","",IF(ISNUMBER($I2),$I2,IFERROR(IF(ISNUMBER(INDEX(Prestations!$E$5:$E$256,MATCH($G2,Prestations!$B$5:$B$256,0))),INDEX(Prestations!$E$5:$E$256,MATCH($G2,Prestations!$B$5:$B$256,0)),""),""))) | R2: =IFERROR(IF(ISNUMBER($Q2),$Q2*IF($E2="",1,$E2),""),"") | S2: =IFERROR(IF($P2="au nombre",IF(N(INDEX(Règles!$D$5:$D$17,MATCH($O2,Règles!$A$5:$A$17,0)))>0,IF($E2="",1,$E2)/INDEX(Règles!$D$5:$D$17,MATCH($O2,Règles!$A$5:$A$17,0)),""),IF($P2="au prix",IF(AND(ISNUMBER($R2),N(INDEX(Règles!$E$5:$E$17,MATCH($O2,Règles!$A$5:$A$17,0)))>0),$R2/INDEX(Règles!$E$5:$E$17,MATCH($O2,Règles!$A$5:$A$17,0)),""),IF(OR($P2="ne compte pas",$P2="absence"),0,""))),"") | T2: =IF(AND(ISNUMBER($A2),$B2<>"",$G2<>"",$P2<>"absence"),1,0) -> 0 | U2: =IF($T2=1,IF(COUNTIFS($B$2:$B2,$B2,$A$2:$A2,$A2,$T$2:$T2,1)=1,1,0),0) -> 0 | V2: =IF(AND($A2="",$B2="",$G2=""),"",IF(NOT(ISNUMBER($A2)),"Date manquante ou non reconnue",IF($B2="","Technicien manquant",IF(COUNTIF(Production!$A$7:$A$21,$B2)=0,"Technicien absent de la liste (onglet Production)",IF($G2="","Code BPU manquant (colonne G)",IF($O2="?","Code BPU inconnu (onglet Prestations)",IF($P2="?","Catégorie inconnue (onglet Règles)",IF(AND($E2<>"",NOT(ISNUMBER($E2))),"Quantité non reconnue",IF(AND($P2="au prix",NOT(ISNUMBER($Q2))),"Prix sur devis à saisir (colonne I)",IF($S2="","Règle à compléter (onglet Règles)",""))))))))))
O3: =IF($G3="","",IFERROR(INDEX(Prestations!$F$5:$F$256,MATCH($G3,Prestations!$B$5:$B$256,0)),"?")) | P3: =IF($O3="","",IF($O3="?","?",IFERROR(INDEX(Règles!$C$5:$C$17,MATCH($O3,Règles!$A$5:$A$17,0)),"?"))) | Q3: =IF($G3="","",IF(ISNUMBER($I3),$I3,IFERROR(IF(ISNUMBER(INDEX(Prestations!$E$5:$E$256,MATCH($G3,Prestations!$B$5:$B$256,0))),INDEX(Prestations!$E$5:$E$256,MATCH($G3,Prestations!$B$5:$B$256,0)),""),""))) | R3: =IFERROR(IF(ISNUMBER($Q3),$Q3*IF($E3="",1,$E3),""),"") | S3: =IFERROR(IF($P3="au nombre",IF(N(INDEX(Règles!$D$5:$D$17,MATCH($O3,Règles!$A$5:$A$17,0)))>0,IF($E3="",1,$E3)/INDEX(Règles!$D$5:$D$17,MATCH($O3,Règles!$A$5:$A$17,0)),""),IF($P3="au prix",IF(AND(ISNUMBER($R3),N(INDEX(Règles!$E$5:$E$17,MATCH($O3,Règles!$A$5:$A$17,0)))>0),$R3/INDEX(Règles!$E$5:$E$17,MATCH($O3,Règles!$A$5:$A$17,0)),""),IF(OR($P3="ne compte pas",$P3="absence"),0,""))),"") | T3: =IF(AND(ISNUMBER($A3),$B3<>"",$G3<>"",$P3<>"absence"),1,0) -> 0 | U3: =IF($T3=1,IF(COUNTIFS($B$2:$B3,$B3,$A$2:$A3,$A3,$T$2:$T3,1)=1,1,0),0) -> 0 | V3: =IF(AND($A3="",$B3="",$G3=""),"",IF(NOT(ISNUMBER($A3)),"Date manquante ou non reconnue",IF($B3="","Technicien manquant",IF(COUNTIF(Production!$A$7:$A$21,$B3)=0,"Technicien absent de la liste (onglet Production)",IF($G3="","Code BPU manquant (colonne G)",IF($O3="?","Code BPU inconnu (onglet Prestations)",IF($P3="?","Catégorie inconnue (onglet Règles)",IF(AND($E3<>"",NOT(ISNUMBER($E3))),"Quantité non reconnue",IF(AND($P3="au prix",NOT(ISNUMBER($Q3))),"Prix sur devis à saisir (colonne I)",IF($S3="","Règle à compléter (onglet Règles)",""))))))))))
O4: =IF($G4="","",IFERROR(INDEX(Prestations!$F$5:$F$256,MATCH($G4,Prestations!$B$5:$B$256,0)),"?")) | P4: =IF($O4="","",IF($O4="?","?",IFERROR(INDEX(Règles!$C$5:$C$17,MATCH($O4,Règles!$A$5:$A$17,0)),"?"))) | Q4: =IF($G4="","",IF(ISNUMBER($I4),$I4,IFERROR(IF(ISNUMBER(INDEX(Prestations!$E$5:$E$256,MATCH($G4,Prestations!$B$5:$B$256,0))),INDEX(Prestations!$E$5:$E$256,MATCH($G4,Prestations!$B$5:$B$256,0)),""),""))) | R4: =IFERROR(IF(ISNUMBER($Q4),$Q4*IF($E4="",1,$E4),""),"") | S4: =IFERROR(IF($P4="au nombre",IF(N(INDEX(Règles!$D$5:$D$17,MATCH($O4,Règles!$A$5:$A$17,0)))>0,IF($E4="",1,$E4)/INDEX(Règles!$D$5:$D$17,MATCH($O4,Règles!$A$5:$A$17,0)),""),IF($P4="au prix",IF(AND(ISNUMBER($R4),N(INDEX(Règles!$E$5:$E$17,MATCH($O4,Règles!$A$5:$A$17,0)))>0),$R4/INDEX(Règles!$E$5:$E$17,MATCH($O4,Règles!$A$5:$A$17,0)),""),IF(OR($P4="ne compte pas",$P4="absence"),0,""))),"") | T4: =IF(AND(ISNUMBER($A4),$B4<>"",$G4<>"",$P4<>"absence"),1,0) -> 0 | U4: =IF($T4=1,IF(COUNTIFS($B$2:$B4,$B4,$A$2:$A4,$A4,$T$2:$T4,1)=1,1,0),0) -> 0 | V4: =IF(AND($A4="",$B4="",$G4=""),"",IF(NOT(ISNUMBER($A4)),"Date manquante ou non reconnue",IF($B4="","Technicien manquant",IF(COUNTIF(Production!$A$7:$A$21,$B4)=0,"Technicien absent de la liste (onglet Production)",IF($G4="","Code BPU manquant (colonne G)",IF($O4="?","Code BPU inconnu (onglet Prestations)",IF($P4="?","Catégorie inconnue (onglet Règles)",IF(AND($E4<>"",NOT(ISNUMBER($E4))),"Quantité non reconnue",IF(AND($P4="au prix",NOT(ISNUMBER($Q4))),"Prix sur devis à saisir (colonne I)",IF($S4="","Règle à compléter (onglet Règles)",""))))))))))
O5: =IF($G5="","",IFERROR(INDEX(Prestations!$F$5:$F$256,MATCH($G5,Prestations!$B$5:$B$256,0)),"?")) | P5: =IF($O5="","",IF($O5="?","?",IFERROR(INDEX(Règles!$C$5:$C$17,MATCH($O5,Règles!$A$5:$A$17,0)),"?"))) | Q5: =IF($G5="","",IF(ISNUMBER($I5),$I5,IFERROR(IF(ISNUMBER(INDEX(Prestations!$E$5:$E$256,MATCH($G5,Prestations!$B$5:$B$256,0))),INDEX(Prestations!$E$5:$E$256,MATCH($G5,Prestations!$B$5:$B$256,0)),""),""))) | R5: =IFERROR(IF(ISNUMBER($Q5),$Q5*IF($E5="",1,$E5),""),"") | S5: =IFERROR(IF($P5="au nombre",IF(N(INDEX(Règles!$D$5:$D$17,MATCH($O5,Règles!$A$5:$A$17,0)))>0,IF($E5="",1,$E5)/INDEX(Règles!$D$5:$D$17,MATCH($O5,Règles!$A$5:$A$17,0)),""),IF($P5="au prix",IF(AND(ISNUMBER($R5),N(INDEX(Règles!$E$5:$E$17,MATCH($O5,Règles!$A$5:$A$17,0)))>0),$R5/INDEX(Règles!$E$5:$E$17,MATCH($O5,Règles!$A$5:$A$17,0)),""),IF(OR($P5="ne compte pas",$P5="absence"),0,""))),"") | T5: =IF(AND(ISNUMBER($A5),$B5<>"",$G5<>"",$P5<>"absence"),1,0) -> 0 | U5: =IF($T5=1,IF(COUNTIFS($B$2:$B5,$B5,$A$2:$A5,$A5,$T$2:$T5,1)=1,1,0),0) -> 0 | V5: =IF(AND($A5="",$B5="",$G5=""),"",IF(NOT(ISNUMBER($A5)),"Date manquante ou non reconnue",IF($B5="","Technicien manquant",IF(COUNTIF(Production!$A$7:$A$21,$B5)=0,"Technicien absent de la liste (onglet Production)",IF($G5="","Code BPU manquant (colonne G)",IF($O5="?","Code BPU inconnu (onglet Prestations)",IF($P5="?","Catégorie inconnue (onglet Règles)",IF(AND($E5<>"",NOT(ISNUMBER($E5))),"Quantité non reconnue",IF(AND($P5="au prix",NOT(ISNUMBER($Q5))),"Prix sur devis à saisir (colonne I)",IF($S5="","Règle à compléter (onglet Règles)",""))))))))))
O6: =IF($G6="","",IFERROR(INDEX(Prestations!$F$5:$F$256,MATCH($G6,Prestations!$B$5:$B$256,0)),"?")) | P6: =IF($O6="","",IF($O6="?","?",IFERROR(INDEX(Règles!$C$5:$C$17,MATCH($O6,Règles!$A$5:$A$17,0)),"?"))) | Q6: =IF($G6="","",IF(ISNUMBER($I6),$I6,IFERROR(IF(ISNUMBER(INDEX(Prestations!$E$5:$E$256,MATCH($G6,Prestations!$B$5:$B$256,0))),INDEX(Prestations!$E$5:$E$256,MATCH($G6,Prestations!$B$5:$B$256,0)),""),""))) | R6: =IFERROR(IF(ISNUMBER($Q6),$Q6*IF($E6="",1,$E6),""),"") | S6: =IFERROR(IF($P6="au nombre",IF(N(INDEX(Règles!$D$5:$D$17,MATCH($O6,Règles!$A$5:$A$17,0)))>0,IF($E6="",1,$E6)/INDEX(Règles!$D$5:$D$17,MATCH($O6,Règles!$A$5:$A$17,0)),""),IF($P6="au prix",IF(AND(ISNUMBER($R6),N(INDEX(Règles!$E$5:$E$17,MATCH($O6,Règles!$A$5:$A$17,0)))>0),$R6/INDEX(Règles!$E$5:$E$17,MATCH($O6,Règles!$A$5:$A$17,0)),""),IF(OR($P6="ne compte pas",$P6="absence"),0,""))),"") | T6: =IF(AND(ISNUMBER($A6),$B6<>"",$G6<>"",$P6<>"absence"),1,0) -> 0 | U6: =IF($T6=1,IF(COUNTIFS($B$2:$B6,$B6,$A$2:$A6,$A6,$T$2:$T6,1)=1,1,0),0) -> 0 | V6: =IF(AND($A6="",$B6="",$G6=""),"",IF(NOT(ISNUMBER($A6)),"Date manquante ou non reconnue",IF($B6="","Technicien manquant",IF(COUNTIF(Production!$A$7:$A$21,$B6)=0,"Technicien absent de la liste (onglet Production)",IF($G6="","Code BPU manquant (colonne G)",IF($O6="?","Code BPU inconnu (onglet Prestations)",IF($P6="?","Catégorie inconnue (onglet Règles)",IF(AND($E6<>"",NOT(ISNUMBER($E6))),"Quantité non reconnue",IF(AND($P6="au prix",NOT(ISNUMBER($Q6))),"Prix sur devis à saisir (colonne I)",IF($S6="","Règle à compléter (onglet Règles)",""))))))))))
O7: =IF($G7="","",IFERROR(INDEX(Prestations!$F$5:$F$256,MATCH($G7,Prestations!$B$5:$B$256,0)),"?")) | P7: =IF($O7="","",IF($O7="?","?",IFERROR(INDEX(Règles!$C$5:$C$17,MATCH($O7,Règles!$A$5:$A$17,0)),"?"))) | Q7: =IF($G7="","",IF(ISNUMBER($I7),$I7,IFERROR(IF(ISNUMBER(INDEX(Prestations!$E$5:$E$256,MATCH($G7,Prestations!$B$5:$B$256,0))),INDEX(Prestations!$E$5:$E$256,MATCH($G7,Prestations!$B$5:$B$256,0)),""),""))) | R7: =IFERROR(IF(ISNUMBER($Q7),$Q7*IF($E7="",1,$E7),""),"") | S7: =IFERROR(IF($P7="au nombre",IF(N(INDEX(Règles!$D$5:$D$17,MATCH($O7,Règles!$A$5:$A$17,0)))>0,IF($E7="",1,$E7)/INDEX(Règles!$D$5:$D$17,MATCH($O7,Règles!$A$5:$A$17,0)),""),IF($P7="au prix",IF(AND(ISNUMBER($R7),N(INDEX(Règles!$E$5:$E$17,MATCH($O7,Règles!$A$5:$A$17,0)))>0),$R7/INDEX(Règles!$E$5:$E$17,MATCH($O7,Règles!$A$5:$A$17,0)),""),IF(OR($P7="ne compte pas",$P7="absence"),0,""))),"") | T7: =IF(AND(ISNUMBER($A7),$B7<>"",$G7<>"",$P7<>"absence"),1,0) -> 0 | U7: =IF($T7=1,IF(COUNTIFS($B$2:$B7,$B7,$A$2:$A7,$A7,$T$2:$T7,1)=1,1,0),0) -> 0 | V7: =IF(AND($A7="",$B7="",$G7=""),"",IF(NOT(ISNUMBER($A7)),"Date manquante ou non reconnue",IF($B7="","Technicien manquant",IF(COUNTIF(Production!$A$7:$A$21,$B7)=0,"Technicien absent de la liste (onglet Production)",IF($G7="","Code BPU manquant (colonne G)",IF($O7="?","Code BPU inconnu (onglet Prestations)",IF($P7="?","Catégorie inconnue (onglet Règles)",IF(AND($E7<>"",NOT(ISNUMBER($E7))),"Quantité non reconnue",IF(AND($P7="au prix",NOT(ISNUMBER($Q7))),"Prix sur devis à saisir (colonne I)",IF($S7="","Règle à compléter (onglet Règles)",""))))))))))
O8: =IF($G8="","",IFERROR(INDEX(Prestations!$F$5:$F$256,MATCH($G8,Prestations!$B$5:$B$256,0)),"?")) | P8: =IF($O8="","",IF($O8="?","?",IFERROR(INDEX(Règles!$C$5:$C$17,MATCH($O8,Règles!$A$5:$A$17,0)),"?"))) | Q8: =IF($G8="","",IF(ISNUMBER($I8),$I8,IFERROR(IF(ISNUMBER(INDEX(Prestations!$E$5:$E$256,MATCH($G8,Prestations!$B$5:$B$256,0))),INDEX(Prestations!$E$5:$E$256,MATCH($G8,Prestations!$B$5:$B$256,0)),""),""))) | R8: =IFERROR(IF(ISNUMBER($Q8),$Q8*IF($E8="",1,$E8),""),"") | S8: =IFERROR(IF($P8="au nombre",IF(N(INDEX(Règles!$D$5:$D$17,MATCH($O8,Règles!$A$5:$A$17,0)))>0,IF($E8="",1,$E8)/INDEX(Règles!$D$5:$D$17,MATCH($O8,Règles!$A$5:$A$17,0)),""),IF($P8="au prix",IF(AND(ISNUMBER($R8),N(INDEX(Règles!$E$5:$E$17,MATCH($O8,Règles!$A$5:$A$17,0)))>0),$R8/INDEX(Règles!$E$5:$E$17,MATCH($O8,Règles!$A$5:$A$17,0)),""),IF(OR($P8="ne compte pas",$P8="absence"),0,""))),"") | T8: =IF(AND(ISNUMBER($A8),$B8<>"",$G8<>"",$P8<>"absence"),1,0) -> 0 | U8: =IF($T8=1,IF(COUNTIFS($B$2:$B8,$B8,$A$2:$A8,$A8,$T$2:$T8,1)=1,1,0),0) -> 0 | V8: =IF(AND($A8="",$B8="",$G8=""),"",IF(NOT(ISNUMBER($A8)),"Date manquante ou non reconnue",IF($B8="","Technicien manquant",IF(COUNTIF(Production!$A$7:$A$21,$B8)=0,"Technicien absent de la liste (onglet Production)",IF($G8="","Code BPU manquant (colonne G)",IF($O8="?","Code BPU inconnu (onglet Prestations)",IF($P8="?","Catégorie inconnue (onglet Règles)",IF(AND($E8<>"",NOT(ISNUMBER($E8))),"Quantité non reconnue",IF(AND($P8="au prix",NOT(ISNUMBER($Q8))),"Prix sur devis à saisir (colonne I)",IF($S8="","Règle à compléter (onglet Règles)",""))))))))))
O9: =IF($G9="","",IFERROR(INDEX(Prestations!$F$5:$F$256,MATCH($G9,Prestations!$B$5:$B$256,0)),"?")) | P9: =IF($O9="","",IF($O9="?","?",IFERROR(INDEX(Règles!$C$5:$C$17,MATCH($O9,Règles!$A$5:$A$17,0)),"?"))) | Q9: =IF($G9="","",IF(ISNUMBER($I9),$I9,IFERROR(IF(ISNUMBER(INDEX(Prestations!$E$5:$E$256,MATCH($G9,Prestations!$B$5:$B$256,0))),INDEX(Prestations!$E$5:$E$256,MATCH($G9,Prestations!$B$5:$B$256,0)),""),""))) | R9: =IFERROR(IF(ISNUMBER($Q9),$Q9*IF($E9="",1,$E9),""),"") | S9: =IFERROR(IF($P9="au nombre",IF(N(INDEX(Règles!$D$5:$D$17,MATCH($O9,Règles!$A$5:$A$17,0)))>0,IF($E9="",1,$E9)/INDEX(Règles!$D$5:$D$17,MATCH($O9,Règles!$A$5:$A$17,0)),""),IF($P9="au prix",IF(AND(ISNUMBER($R9),N(INDEX(Règles!$E$5:$E$17,MATCH($O9,Règles!$A$5:$A$17,0)))>0),$R9/INDEX(Règles!$E$5:$E$17,MATCH($O9,Règles!$A$5:$A$17,0)),""),IF(OR($P9="ne compte pas",$P9="absence"),0,""))),"") | T9: =IF(AND(ISNUMBER($A9),$B9<>"",$G9<>"",$P9<>"absence"),1,0) -> 0 | U9: =IF($T9=1,IF(COUNTIFS($B$2:$B9,$B9,$A$2:$A9,$A9,$T$2:$T9,1)=1,1,0),0) -> 0 | V9: =IF(AND($A9="",$B9="",$G9=""),"",IF(NOT(ISNUMBER($A9)),"Date manquante ou non reconnue",IF($B9="","Technicien manquant",IF(COUNTIF(Production!$A$7:$A$21,$B9)=0,"Technicien absent de la liste (onglet Production)",IF($G9="","Code BPU manquant (colonne G)",IF($O9="?","Code BPU inconnu (onglet Prestations)",IF($P9="?","Catégorie inconnue (onglet Règles)",IF(AND($E9<>"",NOT(ISNUMBER($E9))),"Quantité non reconnue",IF(AND($P9="au prix",NOT(ISNUMBER($Q9))),"Prix sur devis à saisir (colonne I)",IF($S9="","Règle à compléter (onglet Règles)",""))))))))))
O10: =IF($G10="","",IFERROR(INDEX(Prestations!$F$5:$F$256,MATCH($G10,Prestations!$B$5:$B$256,0)),"?")) | P10: =IF($O10="","",IF($O10="?","?",IFERROR(INDEX(Règles!$C$5:$C$17,MATCH($O10,Règles!$A$5:$A$17,0)),"?"))) | Q10: =IF($G10="","",IF(ISNUMBER($I10),$I10,IFERROR(IF(ISNUMBER(INDEX(Prestations!$E$5:$E$256,MATCH($G10,Prestations!$B$5:$B$256,0))),INDEX(Prestations!$E$5:$E$256,MATCH($G10,Prestations!$B$5:$B$256,0)),""),""))) | R10: =IFERROR(IF(ISNUMBER($Q10),$Q10*IF($E10="",1,$E10),""),"") | S10: =IFERROR(IF($P10="au nombre",IF(N(INDEX(Règles!$D$5:$D$17,MATCH($O10,Règles!$A$5:$A$17,0)))>0,IF($E10="",1,$E10)/INDEX(Règles!$D$5:$D$17,MATCH($O10,Règles!$A$5:$A$17,0)),""),IF($P10="au prix",IF(AND(ISNUMBER($R10),N(INDEX(Règles!$E$5:$E$17,MATCH($O10,Règles!$A$5:$A$17,0)))>0),$R10/INDEX(Règles!$E$5:$E$17,MATCH($O10,Règles!$A$5:$A$17,0)),""),IF(OR($P10="ne compte pas",$P10="absence"),0,""))),"") | T10: =IF(AND(ISNUMBER($A10),$B10<>"",$G10<>"",$P10<>"absence"),1,0) -> 0 | U10: =IF($T10=1,IF(COUNTIFS($B$2:$B10,$B10,$A$2:$A10,$A10,$T$2:$T10,1)=1,1,0),0) -> 0 | V10: =IF(AND($A10="",$B10="",$G10=""),"",IF(NOT(ISNUMBER($A10)),"Date manquante ou non reconnue",IF($B10="","Technicien manquant",IF(COUNTIF(Production!$A$7:$A$21,$B10)=0,"Technicien absent de la liste (onglet Production)",IF($G10="","Code BPU manquant (colonne G)",IF($O10="?","Code BPU inconnu (onglet Prestations)",IF($P10="?","Catégorie inconnue (onglet Règles)",IF(AND($E10<>"",NOT(ISNUMBER($E10))),"Quantité non reconnue",IF(AND($P10="au prix",NOT(ISNUMBER($Q10))),"Prix sur devis à saisir (colonne I)",IF($S10="","Règle à compléter (onglet Règles)",""))))))))))
O11: =IF($G11="","",IFERROR(INDEX(Prestations!$F$5:$F$256,MATCH($G11,Prestations!$B$5:$B$256,0)),"?")) | P11: =IF($O11="","",IF($O11="?","?",IFERROR(INDEX(Règles!$C$5:$C$17,MATCH($O11,Règles!$A$5:$A$17,0)),"?"))) | Q11: =IF($G11="","",IF(ISNUMBER($I11),$I11,IFERROR(IF(ISNUMBER(INDEX(Prestations!$E$5:$E$256,MATCH($G11,Prestations!$B$5:$B$256,0))),INDEX(Prestations!$E$5:$E$256,MATCH($G11,Prestations!$B$5:$B$256,0)),""),""))) | R11: =IFERROR(IF(ISNUMBER($Q11),$Q11*IF($E11="",1,$E11),""),"") | S11: =IFERROR(IF($P11="au nombre",IF(N(INDEX(Règles!$D$5:$D$17,MATCH($O11,Règles!$A$5:$A$17,0)))>0,IF($E11="",1,$E11)/INDEX(Règles!$D$5:$D$17,MATCH($O11,Règles!$A$5:$A$17,0)),""),IF($P11="au prix",IF(AND(ISNUMBER($R11),N(INDEX(Règles!$E$5:$E$17,MATCH($O11,Règles!$A$5:$A$17,0)))>0),$R11/INDEX(Règles!$E$5:$E$17,MATCH($O11,Règles!$A$5:$A$17,0)),""),IF(OR($P11="ne compte pas",$P11="absence"),0,""))),"") | T11: =IF(AND(ISNUMBER($A11),$B11<>"",$G11<>"",$P11<>"absence"),1,0) -> 0 | U11: =IF($T11=1,IF(COUNTIFS($B$2:$B11,$B11,$A$2:$A11,$A11,$T$2:$T11,1)=1,1,0),0) -> 0 | V11: =IF(AND($A11="",$B11="",$G11=""),"",IF(NOT(ISNUMBER($A11)),"Date manquante ou non reconnue",IF($B11="","Technicien manquant",IF(COUNTIF(Production!$A$7:$A$21,$B11)=0,"Technicien absent de la liste (onglet Production)",IF($G11="","Code BPU manquant (colonne G)",IF($O11="?","Code BPU inconnu (onglet Prestations)",IF($P11="?","Catégorie inconnue (onglet Règles)",IF(AND($E11<>"",NOT(ISNUMBER($E11))),"Quantité non reconnue",IF(AND($P11="au prix",NOT(ISNUMBER($Q11))),"Prix sur devis à saisir (colonne I)",IF($S11="","Règle à compléter (onglet Règles)",""))))))))))
O12: =IF($G12="","",IFERROR(INDEX(Prestations!$F$5:$F$256,MATCH($G12,Prestations!$B$5:$B$256,0)),"?")) | P12: =IF($O12="","",IF($O12="?","?",IFERROR(INDEX(Règles!$C$5:$C$17,MATCH($O12,Règles!$A$5:$A$17,0)),"?"))) | Q12: =IF($G12="","",IF(ISNUMBER($I12),$I12,IFERROR(IF(ISNUMBER(INDEX(Prestations!$E$5:$E$256,MATCH($G12,Prestations!$B$5:$B$256,0))),INDEX(Prestations!$E$5:$E$256,MATCH($G12,Prestations!$B$5:$B$256,0)),""),""))) | R12: =IFERROR(IF(ISNUMBER($Q12),$Q12*IF($E12="",1,$E12),""),"") | S12: =IFERROR(IF($P12="au nombre",IF(N(INDEX(Règles!$D$5:$D$17,MATCH($O12,Règles!$A$5:$A$17,0)))>0,IF($E12="",1,$E12)/INDEX(Règles!$D$5:$D$17,MATCH($O12,Règles!$A$5:$A$17,0)),""),IF($P12="au prix",IF(AND(ISNUMBER($R12),N(INDEX(Règles!$E$5:$E$17,MATCH($O12,Règles!$A$5:$A$17,0)))>0),$R12/INDEX(Règles!$E$5:$E$17,MATCH($O12,Règles!$A$5:$A$17,0)),""),IF(OR($P12="ne compte pas",$P12="absence"),0,""))),"") | T12: =IF(AND(ISNUMBER($A12),$B12<>"",$G12<>"",$P12<>"absence"),1,0) -> 0 | U12: =IF($T12=1,IF(COUNTIFS($B$2:$B12,$B12,$A$2:$A12,$A12,$T$2:$T12,1)=1,1,0),0) -> 0 | V12: =IF(AND($A12="",$B12="",$G12=""),"",IF(NOT(ISNUMBER($A12)),"Date manquante ou non reconnue",IF($B12="","Technicien manquant",IF(COUNTIF(Production!$A$7:$A$21,$B12)=0,"Technicien absent de la liste (onglet Production)",IF($G12="","Code BPU manquant (colonne G)",IF($O12="?","Code BPU inconnu (onglet Prestations)",IF($P12="?","Catégorie inconnue (onglet Règles)",IF(AND($E12<>"",NOT(ISNUMBER($E12))),"Quantité non reconnue",IF(AND($P12="au prix",NOT(ISNUMBER($Q12))),"Prix sur devis à saisir (colonne I)",IF($S12="","Règle à compléter (onglet Règles)",""))))))))))
O13: =IF($G13="","",IFERROR(INDEX(Prestations!$F$5:$F$256,MATCH($G13,Prestations!$B$5:$B$256,0)),"?")) | P13: =IF($O13="","",IF($O13="?","?",IFERROR(INDEX(Règles!$C$5:$C$17,MATCH($O13,Règles!$A$5:$A$17,0)),"?"))) | Q13: =IF($G13="","",IF(ISNUMBER($I13),$I13,IFERROR(IF(ISNUMBER(INDEX(Prestations!$E$5:$E$256,MATCH($G13,Prestations!$B$5:$B$256,0))),INDEX(Prestations!$E$5:$E$256,MATCH($G13,Prestations!$B$5:$B$256,0)),""),""))) | R13: =IFERROR(IF(ISNUMBER($Q13),$Q13*IF($E13="",1,$E13),""),"") | S13: =IFERROR(IF($P13="au nombre",IF(N(INDEX(Règles!$D$5:$D$17,MATCH($O13,Règles!$A$5:$A$17,0)))>0,IF($E13="",1,$E13)/INDEX(Règles!$D$5:$D$17,MATCH($O13,Règles!$A$5:$A$17,0)),""),IF($P13="au prix",IF(AND(ISNUMBER($R13),N(INDEX(Règles!$E$5:$E$17,MATCH($O13,Règles!$A$5:$A$17,0)))>0),$R13/INDEX(Règles!$E$5:$E$17,MATCH($O13,Règles!$A$5:$A$17,0)),""),IF(OR($P13="ne compte pas",$P13="absence"),0,""))),"") | T13: =IF(AND(ISNUMBER($A13),$B13<>"",$G13<>"",$P13<>"absence"),1,0) -> 0 | U13: =IF($T13=1,IF(COUNTIFS($B$2:$B13,$B13,$A$2:$A13,$A13,$T$2:$T13,1)=1,1,0),0) -> 0 | V13: =IF(AND($A13="",$B13="",$G13=""),"",IF(NOT(ISNUMBER($A13)),"Date manquante ou non reconnue",IF($B13="","Technicien manquant",IF(COUNTIF(Production!$A$7:$A$21,$B13)=0,"Technicien absent de la liste (onglet Production)",IF($G13="","Code BPU manquant (colonne G)",IF($O13="?","Code BPU inconnu (onglet Prestations)",IF($P13="?","Catégorie inconnue (onglet Règles)",IF(AND($E13<>"",NOT(ISNUMBER($E13))),"Quantité non reconnue",IF(AND($P13="au prix",NOT(ISNUMBER($Q13))),"Prix sur devis à saisir (colonne I)",IF($S13="","Règle à compléter (onglet Règles)",""))))))))))
... O5001: =IF($G5001="","",IFERROR(INDEX(Prestations!$F$5:$F$256,MATCH($G5001,Prestations!$B$5:$B$256,0)),"?")) | P5001: =IF($O5001="","",IF($O5001="?","?",IFERROR(INDEX(Règles!$C$5:$C$17,MATCH($O5001,Règles!$A$5:$A$17,0)),"?"))) | Q5001: =IF($G5001="","",IF(ISNUMBER($I5001),$I5001,IFERROR(IF(ISNUMBER(INDEX(Prestations!$E$5:$E$256,MATCH($G5001,Prestations!$B$5:$B$256,0))),INDEX(Prestations!$E$5:$E$256,MATCH($G5001,Prestations!$B$5:$B$256,0)),""),""))) | R5001: =IFERROR(IF(ISNUMBER($Q5001),$Q5001*IF($E5001="",1,$E5001),""),"") | S5001: =IFERROR(IF($P5001="au nombre",IF(N(INDEX(Règles!$D$5:$D$17,MATCH($O5001,Règles!$A$5:$A$17,0)))>0,IF($E5001="",1,$E5001)/INDEX(Règles!$D$5:$D$17,MATCH($O5001,Règles!$A$5:$A$17,0)),""),IF($P5001="au prix",IF(AND(ISNUMBER($R5001),N(INDEX(Règles!$E$5:$E$17,MATCH($O5001,Règles!$A$5:$A$17,0)))>0),$R5001/INDEX(Règles!$E$5:$E$17,MATCH($O5001,Règles!$A$5:$A$17,0)),""),IF(OR($P5001="ne compte pas",$P5001="absence"),0,""))),"") | T5001: =IF(AND(ISNUMBER($A5001),$B5001<>"",$G5001<>"",$P5001<>"absence"),1,0) -> 0 | U5001: =IF($T5001=1,IF(COUNTIFS($B$2:$B5001,$B5001,$A$2:$A5001,$A5001,$T$2:$T5001,1)=1,1,0),0) -> 0 | V5001: =IF(AND($A5001="",$B5001="",$G5001=""),"",IF(NOT(ISNUMBER($A5001)),"Date manquante ou non reconnue",IF($B5001="","Technicien manquant",IF(COUNTIF(Production!$A$7:$A$21,$B5001)=0,"Technicien absent de la liste (onglet Production)",IF($G5001="","Code BPU manquant (colonne G)",IF($O5001="?","Code BPU inconnu (onglet Prestations)",IF($P5001="?","Catégorie inconnue (onglet Règles)",IF(AND($E5001<>"",NOT(ISNUMBER($E5001))),"Quantité non reconnue",IF(AND($P5001="au prix",NOT(ISNUMBER($Q5001))),"Prix sur devis à saisir (colonne I)",IF($S5001="","Règle à compléter (onglet Règles)",""))))))))))

Sheet Règles
A1: RÈGLES : COMBIEN DANS UNE JOURNÉE NORMALE ?
A2: Change seulement les cases jaunes. « au nombre » : 1 unité = 1/(colonne D) de journée. « au prix » : prix de la prestation ÷ valeur d'une journée (colonne E).
A4: Catégorie | B4: Ce qu'on compte | C4: Comment ça compte | D4: Combien dans une journée normale | E4: Valeur d'une journée (€) | F4: Résultat | G4: Remarque
A5: AXIONE · City Fast | B5: intervention | C5: au nombre | D5: 4 | F5: =IF(C5="au nombre",IF(N(D5)>0,"1 "&B5&" = 1/"&D5&" de journée","À COMPLÉTER : combien par jour ?"),IF(C5="au prix",IF(N(E5)>0,"son prix ÷ "&ROUND(E5,0)&" €","À COMPLÉTER"),IF(C5="absence","jour non travaillé","0 : ne compte pas"))) -> 1 intervention = 1/4 de journée | G5: D'après toi : 4 par jour, pour N1, N2 et N3. Si un N3 (tirage de câble) prend plus longtemps, on peut le mettre à part.
A6: Heure de technicien | B6: heure | C6: au nombre | D6: 7 | F6: =IF(C6="au nombre",IF(N(D6)>0,"1 "&B6&" = 1/"&D6&" de journée","À COMPLÉTER : combien par jour ?"),IF(C6="au prix",IF(N(E6)>0,"son prix ÷ "&ROUND(E6,0)&" €","À COMPLÉTER"),IF(C6="absence","jour non travaillé","0 : ne compte pas"))) -> 1 heure = 1/7 de journée | G6: AXIONE RHD57 et heures COVAGE (56.4, 63.1, 63.2). Journée de 7 h : mets 8 si vos journées font 8 h. « 2 techniciens + nacelle » : seul celui qui saisit la ligne est compté.
A7: COVAGE · Ticket | B7: ticket | C7: au nombre | D7: 2 | F7: =IF(C7="au nombre",IF(N(D7)>0,"1 "&B7&" = 1/"&D7&" de journée","À COMPLÉTER : combien par jour ?"),IF(C7="au prix",IF(N(E7)>0,"son prix ÷ "&ROUND(E7,0)&" €","À COMPLÉTER"),IF(C7="absence","jour non travaillé","0 : ne compte pas"))) -> 1 ticket = 1/2 de journée | G7: D'après toi : 2 par jour (sites éloignés).
A8: COVAGE · Autres prestations | B8: prestation | C8: au prix | E8: =IFERROR(D7*INDEX(Prestations!$E$5:$E$256,MATCH("COVAGE-TICKET",Prestations!$B$5:$B$256,0)),"") -> 800 | F8: =IF(C8="au nombre",IF(N(D8)>0,"1 "&B8&" = 1/"&D8&" de journée","À COMPLÉTER : combien par jour ?"),IF(C8="au prix",IF(N(E8)>0,"son prix ÷ "&ROUND(E8,0)&" €","À COMPLÉTER"),IF(C8="absence","jour non travaillé","0 : ne compte pas"))) -> son prix ÷ 800 € | G8: Raccordements, câble, boîtes, études… comptés au prix : 1 journée = ce que rapporte une journée de tickets COVAGE. Tu peux taper une autre valeur en E.
A9: ALTITUDE · Ticket | B9: ticket | C9: au nombre | D9: 4 | F9: =IF(C9="au nombre",IF(N(D9)>0,"1 "&B9&" = 1/"&D9&" de journée","À COMPLÉTER : combien par jour ?"),IF(C9="au prix",IF(N(E9)>0,"son prix ÷ "&ROUND(E9,0)&" €","À COMPLÉTER"),IF(C9="absence","jour non travaillé","0 : ne compte pas"))) -> 1 ticket = 1/4 de journée | G9: D'après toi : 4 par jour.
A10: ALTITUDE · Malfaçons | B10: malfaçon | C10: au prix | E10: =IFERROR(D9*INDEX(Prestations!$E$5:$E$256,MATCH("ALTITUDE-TICKET",Prestations!$B$5:$B$256,0)),"") -> 852 | F10: =IF(C10="au nombre",IF(N(D10)>0,"1 "&B10&" = 1/"&D10&" de journée","À COMPLÉTER : combien par jour ?"),IF(C10="au prix",IF(N(E10)>0,"son prix ÷ "&ROUND(E10,0)&" €","À COMPLÉTER"),IF(C10="absence","jour non travaillé","0 : ne compte pas"))) -> son prix ÷ 852 € | G10: Au prix d'une journée de tickets ALTITUDE : une malfaçon aérienne (200 €) ≈ 1 ticket, une souterraine (100 €) ≈ ½ ticket. À vérifier.
A11: LOSANGE · Ticket | B11: ticket | C11: au nombre | D11: 4 | F11: =IF(C11="au nombre",IF(N(D11)>0,"1 "&B11&" = 1/"&D11&" de journée","À COMPLÉTER : combien par jour ?"),IF(C11="au prix",IF(N(E11)>0,"son prix ÷ "&ROUND(E11,0)&" €","À COMPLÉTER"),IF(C11="absence","jour non travaillé","0 : ne compte pas"))) -> 1 ticket = 1/4 de journée | G11: D'après toi : 4 par jour.
A12: LOSANGE · Malfaçons | B12: malfaçon | C12: au prix | E12: =IFERROR(D11*INDEX(Prestations!$E$5:$E$256,MATCH("LOSANGE-TICKET",Prestations!$B$5:$B$256,0)),"") -> 828 | F12: =IF(C12="au nombre",IF(N(D12)>0,"1 "&B12&" = 1/"&D12&" de journée","À COMPLÉTER : combien par jour ?"),IF(C12="au prix",IF(N(E12)>0,"son prix ÷ "&ROUND(E12,0)&" €","À COMPLÉTER"),IF(C12="absence","jour non travaillé","0 : ne compte pas"))) -> son prix ÷ 828 € | G12: Comme ALTITUDE, au prix d'une journée de tickets LOSANGE. À vérifier.
A13: IELO · Ticket | B13: ticket | C13: au nombre | D13: 2 | F13: =IF(C13="au nombre",IF(N(D13)>0,"1 "&B13&" = 1/"&D13&" de journée","À COMPLÉTER : combien par jour ?"),IF(C13="au prix",IF(N(E13)>0,"son prix ÷ "&ROUND(E13,0)&" €","À COMPLÉTER"),IF(C13="absence","jour non travaillé","0 : ne compte pas"))) -> 1 ticket = 1/2 de journée | G13: D'après toi : 2 par jour (sites éloignés).
A14: CELESTE · SAV | B14: SAV | C14: au nombre | D14: 2 | F14: =IF(C14="au nombre",IF(N(D14)>0,"1 "&B14&" = 1/"&D14&" de journée","À COMPLÉTER : combien par jour ?"),IF(C14="au prix",IF(N(E14)>0,"son prix ÷ "&ROUND(E14,0)&" €","À COMPLÉTER"),IF(C14="absence","jour non travaillé","0 : ne compte pas"))) -> 1 SAV = 1/2 de journée | G14: D'après toi : 2 par jour, pour F0, F1 et F2. Si un F2 prend plus longtemps, on peut le mettre à part.
A15: FREE · Ticket | B15: ticket | C15: au nombre | F15: =IF(C15="au nombre",IF(N(D15)>0,"1 "&B15&" = 1/"&D15&" de journée","À COMPLÉTER : combien par jour ?"),IF(C15="au prix",IF(N(E15)>0,"son prix ÷ "&ROUND(E15,0)&" €","À COMPLÉTER"),IF(C15="absence","jour non travaillé","0 : ne compte pas"))) -> À COMPLÉTER : combien par jour ? | G15: À compléter : combien de tickets FREE par jour ? Le prix du ticket FREE manque aussi dans le BPU.
A16: Ne compte pas | B16: — | C16: ne compte pas | F16: =IF(C16="au nombre",IF(N(D16)>0,"1 "&B16&" = 1/"&D16&" de journée","À COMPLÉTER : combien par jour ?"),IF(C16="au prix",IF(N(E16)>0,"son prix ÷ "&ROUND(E16,0)&" €","À COMPLÉTER"),IF(C16="absence","jour non travaillé","0 : ne compte pas"))) -> 0 : ne compte pas | G16: Location de nacelle, plus-values de câble, rendez-vous, majoration hotline : de l'argent en plus, pas du travail en plus.
A17: Absence | B17: — | C17: absence | F17: =IF(C17="au nombre",IF(N(D17)>0,"1 "&B17&" = 1/"&D17&" de journée","À COMPLÉTER : combien par jour ?"),IF(C17="au prix",IF(N(E17)>0,"son prix ÷ "&ROUND(E17,0)&" €","À COMPLÉTER"),IF(C17="absence","jour non travaillé","0 : ne compte pas"))) -> jour non travaillé | G17: Congés et absences : le jour n'est pas compté comme travaillé, il ne fait donc pas baisser le taux.

Sheet Prestations
A1: PRESTATIONS DU BPU ET CE QU'ELLES VALENT EN JOURNÉES
A2: Si une prestation est mal comptée, change sa catégorie en colonne F (cases jaunes). Les prix servent au CA et aux règles « au prix ».
A4: Marché | B4: Code BPU | C4: Prestation | D4: Unité | E4: Prix client (€) | F4: Catégorie | G4: Vaut (journée) pour 1
A5: AXIONE | B5: MC-T1 | C5: RHD57 · Heure technicien HO · intervention immédiate | D5: Forfait par heure | E5: 35.93 | F5: Heure de technicien | G5: =IFERROR(IF(INDEX(Règles!$C$5:$C$17,MATCH($F5,Règles!$A$5:$A$17,0))="au nombre",IF(N(INDEX(Règles!$D$5:$D$17,MATCH($F5,Règles!$A$5:$A$17,0)))>0,1/INDEX(Règles!$D$5:$D$17,MATCH($F5,Règles!$A$5:$A$17,0)),""),IF(INDEX(Règles!$C$5:$C$17,MATCH($F5,Règles!$A$5:$A$17,0))="au prix",IF(AND(ISNUMBER($E5),N(INDEX(Règles!$E$5:$E$17,MATCH($F5,Règles!$A$5:$A$17,0)))>0),$E5/INDEX(Règles!$E$5:$E$17,MATCH($F5,Règles!$A$5:$A$17,0)),""),0)),"") -> 0.14285714
A6: AXIONE | B6: MC-T2 | C6: RHD57 · Heure technicien HO · intervention programmée | D6: Forfait par heure | E6: 35.05 | F6: Heure de technicien | G6: =IFERROR(IF(INDEX(Règles!$C$5:$C$17,MATCH($F6,Règles!$A$5:$A$17,0))="au nombre",IF(N(INDEX(Règles!$D$5:$D$17,MATCH($F6,Règles!$A$5:$A$17,0)))>0,1/INDEX(Règles!$D$5:$D$17,MATCH($F6,Règles!$A$5:$A$17,0)),""),IF(INDEX(Règles!$C$5:$C$17,MATCH($F6,Règles!$A$5:$A$17,0))="au prix",IF(AND(ISNUMBER($E6),N(INDEX(Règles!$E$5:$E$17,MATCH($F6,Règles!$A$5:$A$17,0)))>0),$E6/INDEX(Règles!$E$5:$E$17,MATCH($F6,Règles!$A$5:$A$17,0)),""),0)),"") -> 0.14285714
A7: AXIONE | B7: MC-T3 | C7: RHD57 · Heure technicien HNO | D7: Forfait par heure | E7: 55.17 | F7: Heure de technicien | G7: =IFERROR(IF(INDEX(Règles!$C$5:$C$17,MATCH($F7,Règles!$A$5:$A$17,0))="au nombre",IF(N(INDEX(Règles!$D$5:$D$17,MATCH($F7,Règles!$A$5:$A$17,0)))>0,1/INDEX(Règles!$D$5:$D$17,MATCH($F7,Règles!$A$5:$A$17,0)),""),IF(INDEX(Règles!$C$5:$C$17,MATCH($F7,Règles!$A$5:$A$17,0))="au prix",IF(AND(ISNUMBER($E7),N(INDEX(Règles!$E$5:$E$17,MATCH($F7,Règles!$A$5:$A$17,0)))>0),$E7/INDEX(Règles!$E$5:$E$17,MATCH($F7,Règles!$A$5:$A$17,0)),""),0)),"") -> 0.14285714
A8: AXIONE | B8: MC-T4 | C8: RHD57 · 2 techniciens + nacelle ≤ 16 m · HO | D8: Forfait par heure | E8: 73.72 | F8: Heure de technicien | G8: =IFERROR(IF(INDEX(Règles!$C$5:$C$17,MATCH($F8,Règles!$A$5:$A$17,0))="au nombre",IF(N(INDEX(Règles!$D$5:$D$17,MATCH($F8,Règles!$A$5:$A$17,0)))>0,1/INDEX(Règles!$D$5:$D$17,MATCH($F8,Règles!$A$5:$A$17,0)),""),IF(INDEX(Règles!$C$5:$C$17,MATCH($F8,Règles!$A$5:$A$17,0))="au prix",IF(AND(ISNUMBER($E8),N(INDEX(Règles!$E$5:$E$17,MATCH($F8,Règles!$A$5:$A$17,0)))>0),$E8/INDEX(Règles!$E$5:$E$17,MATCH($F8,Règles!$A$5:$A$17,0)),""),0)),"") -> 0.14285714
A9: AXIONE | B9: MC-T5 | C9: RHD57 · 2 techniciens + nacelle ≤ 16 m · HNO | D9: Forfait par heure | E9: 123.75 | F9: Heure de technicien | G9: =IFERROR(IF(INDEX(Règles!$C$5:$C$17,MATCH($F9,Règles!$A$5:$A$17,0))="au nombre",IF(N(INDEX(Règles!$D$5:$D$17,MATCH($F9,Règles!$A$5:$A$17,0)))>0,1/INDEX(Règles!$D$5:$D$17,MATCH($F9,Règles!$A$5:$A$17,0)),""),IF(INDEX(Règles!$C$5:$C$17,MATCH($F9,Règles!$A$5:$A$17,0))="au prix",IF(AND(ISNUMBER($E9),N(INDEX(Règles!$E$5:$E$17,MATCH($F9,Règles!$A$5:$A$17,0)))>0),$E9/INDEX(Règles!$E$5:$E$17,MATCH($F9,Règles!$A$5:$A$17,0)),""),0)),"") -> 0.14285714
A10: AXIONE | B10: MC-T6 | C10: RHD57 · Nacelle exceptionnelle > 16 m (par mètre) | D10: Par mètre (hauteur nacelle) | E10: 23.29 | F10: Ne compte pas | G10: =IFERROR(IF(INDEX(Règles!$C$5:$C$17,MATCH($F10,Règles!$A$5:$A$17,0))="au nombre",IF(N(INDEX(Règles!$D$5:$D$17,MATCH($F10,Règles!$A$5:$A$17,0)))>0,1/INDEX(Règles!$D$5:$D$17,MATCH($F10,Règles!$A$5:$A$17,0)),""),IF(INDEX(Règles!$C$5:$C$17,MATCH($F10,Règles!$A$5:$A$17,0))="au prix",IF(AND(ISNUMBER($E10),N(INDEX(Règles!$E$5:$E$17,MATCH($F10,Règles!$A$5:$A$17,0)))>0),$E10/INDEX(Règles!$E$5:$E$17,MATCH($F10,Règles!$A$5:$A$17,0)),""),0)),"") -> 0
A11: AXIONE | B11: CF-N1-URG-HO | C11: City Fast N1 Site (PM, DME) · Urgente 4h · HO 7h-19h | D11: À l'intervention (prix STT) | E11: 310 | F11: AXIONE · City Fast | G11: =IFERROR(IF(INDEX(Règles!$C$5:$C$17,MATCH($F11,Règles!$A$5:$A$17,0))="au nombre",IF(N(INDEX(Règles!$D$5:$D$17,MATCH($F11,Règles!$A$5:$A$17,0)))>0,1/INDEX(Règles!$D$5:$D$17,MATCH($F11,Règles!$A$5:$A$17,0)),""),IF(INDEX(Règles!$C$5:$C$17,MATCH($F11,Règles!$A$5:$A$17,0))="au prix",IF(AND(ISNUMBER($E11),N(INDEX(Règles!$E$5:$E$17,MATCH($F11,Règles!$A$5:$A$17,0)))>0),$E11/INDEX(Règles!$E$5:$E$17,MATCH($F11,Règles!$A$5:$A$17,0)),""),0)),"") -> 0.25
A12: AXIONE | B12: CF-N1-URG-HNO | C12: City Fast N1 Site (PM, DME) · Urgente 4h · HNO 19h-7h | D12: À l'intervention (prix STT) | E12: 490 | F12: AXIONE · City Fast | G12: =IFERROR(IF(INDEX(Règles!$C$5:$C$17,MATCH($F12,Règles!$A$5:$A$17,0))="au nombre",IF(N(INDEX(Règles!$D$5:$D$17,MATCH($F12,Règles!$A$5:$A$17,0)))>0,1/INDEX(Règles!$D$5:$D$17,MATCH($F12,Règles!$A$5:$A$17,0)),""),IF(INDEX(Règles!$C$5:$C$17,MATCH($F12,Règles!$A$5:$A$17,0))="au prix",IF(AND(ISNUMBER($E12),N(INDEX(Règles!$E$5:$E$17,MATCH($F12,Règles!$A$5:$A$17,0)))>0),$E12/INDEX(Règles!$E$5:$E$17,MATCH($F12,Règles!$A$5:$A$17,0)),""),0)),"") -> 0.25
A13: AXIONE | B13: CF-N1-STDPLUS | C13: City Fast N1 Site (PM, DME) · Standard Plus 24h · HO 7h-19h | D13: À l'intervention (prix STT) | E13: 300 | F13: AXIONE · City Fast | G13: =IFERROR(IF(INDEX(Règles!$C$5:$C$17,MATCH($F13,Règles!$A$5:$A$17,0))="au nombre",IF(N(INDEX(Règles!$D$5:$D$17,MATCH($F13,Règles!$A$5:$A$17,0)))>0,1/INDEX(Règles!$D$5:$D$17,MATCH($F13,Règles!$A$5:$A$17,0)),""),IF(INDEX(Règles!$C$5:$C$17,MATCH($F13,Règles!$A$5:$A$17,0))="au prix",IF(AND(ISNUMBER($E13),N(INDEX(Règles!$E$5:$E$17,MATCH($F13,Règles!$A$5:$A$17,0)))>0),$E13/INDEX(Règles!$E$5:$E$17,MATCH($F13,Règles!$A$5:$A$17,0)),""),0)),"") -> 0.25
A14: AXIONE | B14: CF-N1-STD | C14: City Fast N1 Site (PM, DME) · Standard 5j/7 · HO 7h-19h | D14: À l'intervention (prix STT) | E14: 300 | F14: AXIONE · City Fast | G14: =IFERROR(IF(INDEX(Règles!$C$5:$C$17,MATCH($F14,Règles!$A$5:$A$17,0))="au nombre",IF(N(INDEX(Règles!$D$5:$D$17,MATCH($F14,Règles!$A$5:$A$17,0)))>0,1/INDEX(Règles!$D$5:$D$17,MATCH($F14,Règles!$A$5:$A$17,0)),""),IF(INDEX(Règles!$C$5:$C$17,MATCH($F14,Règles!$A$5:$A$17,0))="au prix",IF(AND(ISNUMBER($E14),N(INDEX(Règles!$E$5:$E$17,MATCH($F14,Règles!$A$5:$A$17,0)))>0),$E14/INDEX(Règles!$E$5:$E$17,MATCH($F14,Règles!$A$5:$A$17,0)),""),0)),"") -> 0.25
A15: AXIONE | B15: CF-N2-URG-HO | C15: City Fast N2 Extrémité câble en chambre (BPE) · Urgente 4h · HO 7h-19h | D15: À l'intervention (prix STT) | E15: 370 | F15: AXIONE · City Fast | G15: =IFERROR(IF(INDEX(Règles!$C$5:$C$17,MATCH($F15,Règles!$A$5:$A$17,0))="au nombre",IF(N(INDEX(Règles!$D$5:$D$17,MATCH($F15,Règles!$A$5:$A$17,0)))>0,1/INDEX(Règles!$D$5:$D$17,MATCH($F15,Règles!$A$5:$A$17,0)),""),IF(INDEX(Règles!$C$5:$C$17,MATCH($F15,Règles!$A$5:$A$17,0))="au prix",IF(AND(ISNUMBER($E15),N(INDEX(Règles!$E$5:$E$17,MATCH($F15,Règles!$A$5:$A$17,0)))>0),$E15/INDEX(Règles!$E$5:$E$17,MATCH($F15,Règles!$A$5:$A$17,0)),""),0)),"") -> 0.25
A16: AXIONE | B16: CF-N2-URG-HNO | C16: City Fast N2 Extrémité câble en chambre (BPE) · Urgente 4h · HNO 19h-7h | D16: À l'intervention (prix STT) | E16: 580 | F16: AXIONE · City Fast | G16: =IFERROR(IF(INDEX(Règles!$C$5:$C$17,MATCH($F16,Règles!$A$5:$A$17,0))="au nombre",IF(N(INDEX(Règles!$D$5:$D$17,MATCH($F16,Règles!$A$5:$A$17,0)))>0,1/INDEX(Règles!$D$5:$D$17,MATCH($F16,Règles!$A$5:$A$17,0)),""),IF(INDEX(Règles!$C$5:$C$17,MATCH($F16,Règles!$A$5:$A$17,0))="au prix",IF(AND(ISNUMBER($E16),N(INDEX(Règles!$E$5:$E$17,MATCH($F16,Règles!$A$5:$A$17,0)))>0),$E16/INDEX(Règles!$E$5:$E$17,MATCH($F16,Règles!$A$5:$A$17,0)),""),0)),"") -> 0.25
... A112: COVAGE | B112: COV-12.8 | C112: 12.8 · Tirage de câble sous tube IRO (au ml) | D112: ml | E112: 4.9 | F112: COVAGE · Autres prestations | G112: =IFERROR(IF(INDEX(Règles!$C$5:$C$17,MATCH($F112,Règles!$A$5:$A$17,0))="au nombre",IF(N(INDEX(Règles!$D$5:$D$17,MATCH($F112,Règles!$A$5:$A$17,0)))>0,1/INDEX(Règles!$D$5:$D$17,MATCH($F112,Règles!$A$5:$A$17,0)),""),IF(INDEX(Règles!$C$5:$C$17,MATCH($F112,Règles!$A$5:$A$17,0))="au prix",IF(AND(ISNUMBER($E112),N(INDEX(Règles!$E$5:$E$17,MATCH($F112,Règles!$A$5:$A$17,0)))>0),$E112/INDEX(Règles!$E$5:$E$17,MATCH($F112,Règles!$A$5:$A$17,0)),""),0)),"") -> 0.006125
A113: COVAGE | B113: COV-12.9 | C113: 12.9 · Désamiantage de la zone de percement (devis) | D113: m² | F113: COVAGE · Autres prestations | G113: =IFERROR(IF(INDEX(Règles!$C$5:$C$17,MATCH($F113,Règles!$A$5:$A$17,0))="au nombre",IF(N(INDEX(Règles!$D$5:$D$17,MATCH($F113,Règles!$A$5:$A$17,0)))>0,1/INDEX(Règles!$D$5:$D$17,MATCH($F113,Règles!$A$5:$A$17,0)),""),IF(INDEX(Règles!$C$5:$C$17,MATCH($F113,Règles!$A$5:$A$17,0))="au prix",IF(AND(ISNUMBER($E113),N(INDEX(Règles!$E$5:$E$17,MATCH($F113,Règles!$A$5:$A$17,0)))>0),$E113/INDEX(Règles!$E$5:$E$17,MATCH($F113,Règles!$A$5:$A$17,0)),""),0)),"")
A114: COVAGE | B114: COV-12.10 | C114: 12.10 · Travaux en hauteur > 3,50 m (au ml) | D114: ml | E114: 5.8 | F114: COVAGE · Autres prestations | G114: =IFERROR(IF(INDEX(Règles!$C$5:$C$17,MATCH($F114,Règles!$A$5:$A$17,0))="au nombre",IF(N(INDEX(Règles!$D$5:$D$17,MATCH($F114,Règles!$A$5:$A$17,0)))>0,1/INDEX(Règles!$D$5:$D$17,MATCH($F114,Règles!$A$5:$A$17,0)),""),IF(INDEX(Règles!$C$5:$C$17,MATCH($F114,Règles!$A$5:$A$17,0))="au prix",IF(AND(ISNUMBER($E114),N(INDEX(Règles!$E$5:$E$17,MATCH($F114,Règles!$A$5:$A$17,0)))>0),$E114/INDEX(Règles!$E$5:$E$17,MATCH($F114,Règles!$A$5:$A$17,0)),""),0)),"") -> 0.00725
A115: COVAGE | B115: COV-12.11 | C115: 12.11 · Location de nacelle (par jour) | D115: jour | E115: 450 | F115: Ne compte pas | G115: =IFERROR(IF(INDEX(Règles!$C$5:$C$17,MATCH($F115,Règles!$A$5:$A$17,0))="au nombre",IF(N(INDEX(Règles!$D$5:$D$17,MATCH($F115,Règles!$A$5:$A$17,0)))>0,1/INDEX(Règles!$D$5:$D$17,MATCH($F115,Règles!$A$5:$A$17,0)),""),IF(INDEX(Règles!$C$5:$C$17,MATCH($F115,Règles!$A$5:$A$17,0))="au prix",IF(AND(ISNUMBER($E115),N(INDEX(Règles!$E$5:$E$17,MATCH($F115,Règles!$A$5:$A$17,0)))>0),$E115/INDEX(Règles!$E$5:$E$17,MATCH($F115,Règles!$A$5:$A$17,0)),""),0)),"") -> 0
A116: COVAGE | B116: COV-12.12 | C116: 12.12 · Câble en immeuble 4 FO (au ml) | D116: ml | E116: 4.95 | F116: COVAGE · Autres prestations | G116: =IFERROR(IF(INDEX(Règles!$C$5:$C$17,MATCH($F116,Règles!$A$5:$A$17,0))="au nombre",IF(N(INDEX(Règles!$D$5:$D$17,MATCH($F116,Règles!$A$5:$A$17,0)))>0,1/INDEX(Règles!$D$5:$D$17,MATCH($F116,Règles!$A$5:$A$17,0)),""),IF(INDEX(Règles!$C$5:$C$17,MATCH($F116,Règles!$A$5:$A$17,0))="au prix",IF(AND(ISNUMBER($E116),N(INDEX(Règles!$E$5:$E$17,MATCH($F116,Règles!$A$5:$A$17,0)))>0),$E116/INDEX(Règles!$E$5:$E$17,MATCH($F116,Règles!$A$5:$A$17,0)),""),0)),"") -> 0.0061875
A117: COVAGE | B117: COV-12.13 | C117: 12.13 · Câble en immeuble 12 FO (au ml) | D117: ml | E117: 5.3 | F117: COVAGE · Autres prestations | G117: =IFERROR(IF(INDEX(Règles!$C$5:$C$17,MATCH($F117,Règles!$A$5:$A$17,0))="au nombre",IF(N(INDEX(Règles!$D$5:$D$17,MATCH($F117,Règles!$A$5:$A$17,0)))>0,1/INDEX(Règles!$D$5:$D$17,MATCH($F117,Règles!$A$5:$A$17,0)),""),IF(INDEX(Règles!$C$5:$C$17,MATCH($F117,Règles!$A$5:$A$17,0))="au prix",IF(AND(ISNUMBER($E117),N(INDEX(Règles!$E$5:$E$17,MATCH($F117,Règles!$A$5:$A$17,0)))>0),$E117/INDEX(Règles!$E$5:$E$17,MATCH($F117,Règles!$A$5:$A$17,0)),""),0)),"") -> 0.006625
A118: COVAGE | B118: COV-12.14 | C118: 12.14 · Câble en immeuble 24 FO (au ml) | D118: ml | E118: 5.65 | F118: COVAGE · Autres prestations | G118: =IFERROR(IF(INDEX(Règles!$C$5:$C$17,MATCH($F118,Règles!$A$5:$A$17,0))="au nombre",IF(N(INDEX(Règles!$D$5:$D$17,MATCH($F118,Règles!$A$5:$A$17,0)))>0,1/INDEX(Règles!$D$5:$D$17,MATCH($F118,Règles!$A$5:$A$17,0)),""),IF(INDEX(Règles!$C$5:$C$17,MATCH($F118,Règles!$A$5:$A$17,0))="au prix",IF(AND(ISNUMBER($E118),N(INDEX(Règles!$E$5:$E$17,MATCH($F118,Règles!$A$5:$A$17,0)))>0),$E118/INDEX(Règles!$E$5:$E$17,MATCH($F118,Règles!$A$5:$A$17,0)),""),0)),"") -> 0.0070625
A119: COVAGE | B119: COV-12.15 | C119: 12.15 · Rocade optique en datacenter (devis) | D119: ml | F119: COVAGE · Autres prestations | G119: =IFERROR(IF(INDEX(Règles!$C$5:$C$17,MATCH($F119,Règles!$A$5:$A$17,0))="au nombre",IF(N(INDEX(Règles!$D$5:$D$17,MATCH($F119,Règles!$A$5:$A$17,0)))>0,1/INDEX(Règles!$D$5:$D$17,MATCH($F119,Règles!$A$5:$A$17,0)),""),IF(INDEX(Règles!$C$5:$C$17,MATCH($F119,Règles!$A$5:$A$17,0))="au prix",IF(AND(ISNUMBER($E119),N(INDEX(Règles!$E$5:$E$17,MATCH($F119,Règles!$A$5:$A$17,0)))>0),$E119/INDEX(Règles!$E$5:$E$17,MATCH($F119,Règles!$A$5:$A$17,0)),""),0)),"")
A120: COVAGE | B120: COV-14.1 | C120: 14.1 · Joint droit · 864 FO | D120: U | E120: 5180 | F120: COVAGE · Autres prestations | G120: =IFERROR(IF(INDEX(Règles!$C$5:$C$17,MATCH($F120,Règles!$A$5:$A$17,0))="au nombre",IF(N(INDEX(Règles!$D$5:$D$17,MATCH($F120,Règles!$A$5:$A$17,0)))>0,1/INDEX(Règles!$D$5:$D$17,MATCH($F120,Règles!$A$5:$A$17,0)),""),IF(INDEX(Règles!$C$5:$C$17,MATCH($F120,Règles!$A$5:$A$17,0))="au prix",IF(AND(ISNUMBER($E120),N(INDEX(Règles!$E$5:$E$17,MATCH($F120,Règles!$A$5:$A$17,0)))>0),$E120/INDEX(Règles!$E$5:$E$17,MATCH($F120,Règles!$A$5:$A$17,0)),""),0)),"") -> 6.475
A121: COVAGE | B121: COV-14.2 | C121: 14.2 · Joint droit · 720 FO | D121: U | E121: 4350 | F121: COVAGE · Autres prestations | G121: =IFERROR(IF(INDEX(Règles!$C$5:$C$17,MATCH($F121,Règles!$A$5:$A$17,0))="au nombre",IF(N(INDEX(Règles!$D$5:$D$17,MATCH($F121,Règles!$A$5:$A$17,0)))>0,1/INDEX(Règles!$D$5:$D$17,MATCH($F121,Règles!$A$5:$A$17,0)),""),IF(INDEX(Règles!$C$5:$C$17,MATCH($F121,Règles!$A$5:$A$17,0))="au prix",IF(AND(ISNUMBER($E121),N(INDEX(Règles!$E$5:$E$17,MATCH($F121,Règles!$A$5:$A$17,0)))>0),$E121/INDEX(Règles!$E$5:$E$17,MATCH($F121,Règles!$A$5:$A$17,0)),""),0)),"") -> 5.4375
A122: COVAGE | B122: COV-14.3 | C122: 14.3 · Joint droit · 576 FO | D122: U | E122: 3750 | F122: COVAGE · Autres prestations | G122: =IFERROR(IF(INDEX(Règles!$C$5:$C$17,MATCH($F122,Règles!$A$5:$A$17,0))="au nombre",IF(N(INDEX(Règles!$D$5:$D$17,MATCH($F122,Règles!$A$5:$A$17,0)))>0,1/INDEX(Règles!$D$5:$D$17,MATCH($F122,Règles!$A$5:$A$17,0)),""),IF(INDEX(Règles!$C$5:$C$17,MATCH($F122,Règles!$A$5:$A$17,0))="au prix",IF(AND(ISNUMBER($E122),N(INDEX(Règles!$E$5:$E$17,MATCH($F122,Règles!$A$5:$A$17,0)))>0),$E122/INDEX(Règles!$E$5:$E$17,MATCH($F122,Règles!$A$5:$A$17,0)),""),0)),"") -> 4.6875
A123: COVAGE | B123: COV-14.4 | C123: 14.4 · Joint droit · 432 FO | D123: U | E123: 2850 | F123: COVAGE · Autres prestations | G123: =IFERROR(IF(INDEX(Règles!$C$5:$C$17,MATCH($F123,Règles!$A$5:$A$17,0))="au nombre",IF(N(INDEX(Règles!$D$5:$D$17,MATCH($F123,Règles!$A$5:$A$17,0)))>0,1/INDEX(Règles!$D$5:$D$17,MATCH($F123,Règles!$A$5:$A$17,0)),""),IF(INDEX(Règles!$C$5:$C$17,MATCH($F123,Règles!$A$5:$A$17,0))="au prix",IF(AND(ISNUMBER($E123),N(INDEX(Règles!$E$5:$E$17,MATCH($F123,Règles!$A$5:$A$17,0)))>0),$E123/INDEX(Règles!$E$5:$E$17,MATCH($F123,Règles!$A$5:$A$17,0)),""),0)),"") -> 3.5625
A124: COVAGE | B124: COV-14.5 | C124: 14.5 · Joint droit · 288 FO | D124: U | E124: 1950 | F124: COVAGE · Autres prestations | G124: =IFERROR(IF(INDEX(Règles!$C$5:$C$17,MATCH($F124,Règles!$A$5:$A$17,0))="au nombre",IF(N(INDEX(Règles!$D$5:$D$17,MATCH($F124,Règles!$A$5:$A$17,0)))>0,1/INDEX(Règles!$D$5:$D$17,MATCH($F124,Règles!$A$5:$A$17,0)),""),IF(INDEX(Règles!$C$5:$C$17,MATCH($F124,Règles!$A$5:$A$17,0))="au prix",IF(AND(ISNUMBER($E124),N(INDEX(Règles!$E$5:$E$17,MATCH($F124,Règles!$A$5:$A$17,0)))>0),$E124/INDEX(Règles!$E$5:$E$17,MATCH($F124,Règles!$A$5:$A$17,0)),""),0)),"") -> 2.4375
A125: COVAGE | B125: COV-14.6 | C125: 14.6 · Joint droit · 192 FO | D125: U | E125: 1300 | F125: COVAGE · Autres prestations | G125: =IFERROR(IF(INDEX(Règles!$C$5:$C$17,MATCH($F125,Règles!$A$5:$A$17,0))="au nombre",IF(N(INDEX(Règles!$D$5:$D$17,MATCH($F125,Règles!$A$5:$A$17,0)))>0,1/INDEX(Règles!$D$5:$D$17,MATCH($F125,Règles!$A$5:$A$17,0)),""),IF(INDEX(Règles!$C$5:$C$17,MATCH($F125,Règles!$A$5:$A$17,0))="au prix",IF(AND(ISNUMBER($E125),N(INDEX(Règles!$E$5:$E$17,MATCH($F125,Règles!$A$5:$A$17,0)))>0),$E125/INDEX(Règles!$E$5:$E$17,MATCH($F125,Règles!$A$5:$A$17,0)),""),0)),"") -> 1.625
A126: COVAGE | B126: COV-14.7 | C126: 14.7 · Joint droit · 144 FO | D126: U | E126: 990 | F126: COVAGE · Autres prestations | G126: =IFERROR(IF(INDEX(Règles!$C$5:$C$17,MATCH($F126,Règles!$A$5:$A$17,0))="au nombre",IF(N(INDEX(Règles!$D$5:$D$17,MATCH($F126,Règles!$A$5:$A$17,0)))>0,1/INDEX(Règles!$D$5:$D$17,MATCH($F126,Règles!$A$5:$A$17,0)),""),IF(INDEX(Règles!$C$5:$C$17,MATCH($F126,Règles!$A$5:$A$17,0))="au prix",IF(AND(ISNUMBER($E126),N(INDEX(Règles!$E$5:$E$17,MATCH($F126,Règles!$A$5:$A$17,0)))>0),$E126/INDEX(Règles!$E$5:$E$17,MATCH($F126,Règles!$A$5:$A$17,0)),""),0)),"") -> 1.2375
A127: COVAGE | B127: COV-14.8 | C127: 14.8 · Joint droit · 96 FO | D127: U | E127: 750 | F127: COVAGE · Autres prestations | G127: =IFERROR(IF(INDEX(Règles!$C$5:$C$17,MATCH($F127,Règles!$A$5:$A$17,0))="au nombre",IF(N(INDEX(Règles!$D$5:$D$17,MATCH($F127,Règles!$A$5:$A$17,0)))>0,1/INDEX(Règles!$D$5:$D$17,MATCH($F127,Règles!$A$5:$A$17,0)),""),IF(INDEX(Règles!$C$5:$C$17,MATCH($F127,Règles!$A$5:$A$17,0))="au prix",IF(AND(ISNUMBER($E127),N(INDEX(Règles!$E$5:$E$17,MATCH($F127,Règles!$A$5:$A$17,0)))>0),$E127/INDEX(Règles!$E$5:$E$17,MATCH($F127,Règles!$A$5:$A$17,0)),""),0)),"") -> 0.9375
A128: COVAGE | B128: COV-14.9 | C128: 14.9 · Joint droit · 72 FO | D128: U | E128: 600 | F128: COVAGE · Autres prestations | G128: =IFERROR(IF(INDEX(Règles!$C$5:$C$17,MATCH($F128,Règles!$A$5:$A$17,0))="au nombre",IF(N(INDEX(Règles!$D$5:$D$17,MATCH($F128,Règles!$A$5:$A$17,0)))>0,1/INDEX(Règles!$D$5:$D$17,MATCH($F128,Règles!$A$5:$A$17,0)),""),IF(INDEX(Règles!$C$5:$C$17,MATCH($F128,Règles!$A$5:$A$17,0))="au prix",IF(AND(ISNUMBER($E128),N(INDEX(Règles!$E$5:$E$17,MATCH($F128,Règles!$A$5:$A$17,0)))>0),$E128/INDEX(Règles!$E$5:$E$17,MATCH($F128,Règles!$A$5:$A$17,0)),""),0)),"") -> 0.75
A129: COVAGE | B129: COV-14.10 | C129: 14.10 · Joint droit · 48 FO | D129: U | E129: 435 | F129: COVAGE · Autres prestations | G129: =IFERROR(IF(INDEX(Règles!$C$5:$C$17,MATCH($F129,Règles!$A$5:$A$17,0))="au nombre",IF(N(INDEX(Règles!$D$5:$D$17,MATCH($F129,Règles!$A$5:$A$17,0)))>0,1/INDEX(Règles!$D$5:$D$17,MATCH($F129,Règles!$A$5:$A$17,0)),""),IF(INDEX(Règles!$C$5:$C$17,MATCH($F129,Règles!$A$5:$A$17,0))="au prix",IF(AND(ISNUMBER($E129),N(INDEX(Règles!$E$5:$E$17,MATCH($F129,Règles!$A$5:$A$17,0)))>0),$E129/INDEX(Règles!$E$5:$E$17,MATCH($F129,Règles!$A$5:$A$17,0)),""),0)),"") -> 0.54375
