Workbook

Sheet Devis
A1: Raison sociale | F1: DEVIS | L1: PARAMÈTRES
A2: Adresse | F2: N° de devis | H2: DEV-2026-001 | L2: Taux de TVA | N2: 0.2
A3: Code postal – Ville | F3: Date | H3: 46316 | L3: Autoliquidation TVA | N3: Non
A4: SIRET : | F4: Validité (jours) | H4: 30
A5: N° TVA intracommunautaire : | F5: Valable jusqu'au | H5: =IF(OR(H3="",H4=""),"",H3+H4) -> 46346
A6: Tél. : E-mail : | F6: Réf. client / commande | L6: COMMENT REMPLIR
L7: • Cases jaunes = à remplir. Tout le reste se calcule.
A8: CLIENT | C8: CHANTIER | L8: • Prestation : choisir dans la liste (code · désignation). Unité et prix viennent de l'onglet BPU.
A9: Société | C9: Projet / réseau | D9: Moselle Fibre – RHD57 | L9: • Qté : en ml, unités, heures, fibres… selon l'unité affichée.
A10: Contact | C10: Objet | D10: Exemple : raccordements, SAV et pose de câble (à remplacer) | L10: • PU HT sur devis : seulement pour les lignes « Sur devis » (case orange) ou pour forcer un prix.
A11: Adresse | C11: Site / commune | L11: • Majoration : MC-07 (technicien supplémentaire) ou MC-08 (HNO) multiplie le montant de la ligne par le coefficient du BPU (onglet Majorations).
A12: Code postal – Ville | C12: Base de prix | D12: BPU Moselle Fibre – RHD57 (Maintenance et VDR Optique) | L12: • Les 6 lignes remplies sont un exemple : effacer les colonnes Prestation, Qté et Majoration.
L13: • 30 lignes prévues. Pour en ajouter : insérer des lignes au milieu du tableau, puis recopier une ligne remplie vers le bas.
A14: N° | B14: Prestation (code · désignation BPU) | C14: Unité | D14: Qté | E14: PU HT BPU | F14: PU HT sur devis | G14: Majoration | H14: Montant HT | J14: lig | K14: prix | L14: • Seules les colonnes A à H s'impriment (paysage, une page de large).
A15: =IF($B15="","",COUNTA($B$15:$B15)) -> 1 | B15: RA-F1 · Raccordement abonné Opera Pro (PM) | C15: =IF(OR($J15="",$J15=0),"",INDEX(BPU!$G$2:$G$117,$J15)&"") -> Forfait par opération | D15: 2 | E15: =IF($B15="","",IF($J15=0,"Hors BPU",IF(ISNUMBER($K15),ROUND($K15,2),$K15))) -> 210 | H15: =IF($B15="","",IF(AND($F15="",NOT(ISNUMBER($E15))),"PU à saisir",ROUND(N($D15)*IF($F15<>"",$F15,$E15)*IF($G15="",1,IFERROR(INDEX(Majorations!$C$2:$C$3,MATCH($G15,ListeMajorations,0)),1)),2))) -> 420 | J15: =IF($B15="","",IFERROR(MATCH($B15,ListePrestations,0),0)) -> 1 | K15: =IF(OR($J15="",$J15=0),"",INDEX(BPU!$H$2:$H$117,$J15)) -> 210
A16: =IF($B16="","",COUNTA($B$15:$B16)) -> 2 | B16: MC-01 · Intervention Immédiate en HO TELECOM - opérations sur equipement actif | C16: =IF(OR($J16="",$J16=0),"",INDEX(BPU!$G$2:$G$117,$J16)&"") -> Forfait par intervention | D16: 1 | E16: =IF($B16="","",IF($J16=0,"Hors BPU",IF(ISNUMBER($K16),ROUND($K16,2),$K16))) -> 160.34 | G16: MC-08 · Intervention en HNO | H16: =IF($B16="","",IF(AND($F16="",NOT(ISNUMBER($E16))),"PU à saisir",ROUND(N($D16)*IF($F16<>"",$F16,$E16)*IF($G16="",1,IFERROR(INDEX(Majorations!$C$2:$C$3,MATCH($G16,ListeMajorations,0)),1)),2))) -> 225.73 | J16: =IF($B16="","",IFERROR(MATCH($B16,ListePrestations,0),0)) -> 16 | K16: =IF(OR($J16="",$J16=0),"",INDEX(BPU!$H$2:$H$117,$J16)) -> 160.34179
A17: =IF($B17="","",COUNTA($B$15:$B17)) -> 3 | B17: MC-T1 · Heure de technicien équipé en HO (8h00 – 18h00) - Intervention Immédiate | C17: =IF(OR($J17="",$J17=0),"",INDEX(BPU!$G$2:$G$117,$J17)&"") -> Forfait par heure | D17: 3 | E17: =IF($B17="","",IF($J17=0,"Hors BPU",IF(ISNUMBER($K17),ROUND($K17,2),$K17))) -> 35.93 | H17: =IF($B17="","",IF(AND($F17="",NOT(ISNUMBER($E17))),"PU à saisir",ROUND(N($D17)*IF($F17<>"",$F17,$E17)*IF($G17="",1,IFERROR(INDEX(Majorations!$C$2:$C$3,MATCH($G17,ListeMajorations,0)),1)),2))) -> 107.79 | J17: =IF($B17="","",IFERROR(MATCH($B17,ListePrestations,0),0)) -> 24 | K17: =IF(OR($J17="",$J17=0),"",INDEX(BPU!$H$2:$H$117,$J17)) -> 35.92625
A18: =IF($B18="","",COUNTA($B$15:$B18)) -> 4 | B18: 4.1.1 · Pose de câbles à fibres optiques, G657-A2 ou G652-D , de 1 FO à 144 FO | C18: =IF(OR($J18="",$J18=0),"",INDEX(BPU!$G$2:$G$117,$J18)&"") -> ml | D18: 250 | E18: =IF($B18="","",IF($J18=0,"Hors BPU",IF(ISNUMBER($K18),ROUND($K18,2),$K18))) -> 1 | H18: =IF($B18="","",IF(AND($F18="",NOT(ISNUMBER($E18))),"PU à saisir",ROUND(N($D18)*IF($F18<>"",$F18,$E18)*IF($G18="",1,IFERROR(INDEX(Majorations!$C$2:$C$3,MATCH($G18,ListeMajorations,0)),1)),2))) -> 250 | J18: =IF($B18="","",IFERROR(MATCH($B18,ListePrestations,0),0)) -> 40 | K18: =IF(OR($J18="",$J18=0),"",INDEX(BPU!$H$2:$H$117,$J18)) -> 1
A19: =IF($B19="","",COUNTA($B$15:$B19)) -> 5 | B19: 4.3.2 · Pose boitier pour protection d'épissure, capacité jusqu'à 24 épissures | C19: =IF(OR($J19="",$J19=0),"",INDEX(BPU!$G$2:$G$117,$J19)&"") -> u | D19: 1 | E19: =IF($B19="","",IF($J19=0,"Hors BPU",IF(ISNUMBER($K19),ROUND($K19,2),$K19))) -> 130 | H19: =IF($B19="","",IF(AND($F19="",NOT(ISNUMBER($E19))),"PU à saisir",ROUND(N($D19)*IF($F19<>"",$F19,$E19)*IF($G19="",1,IFERROR(INDEX(Majorations!$C$2:$C$3,MATCH($G19,ListeMajorations,0)),1)),2))) -> 130 | J19: =IF($B19="","",IFERROR(MATCH($B19,ListePrestations,0),0)) -> 51 | K19: =IF(OR($J19="",$J19=0),"",INDEX(BPU!$H$2:$H$117,$J19)) -> 130
A20: =IF($B20="","",COUNTA($B$15:$B20)) -> 6 | B20: 4.8.1 · Raccordement par fibre sur câble optique inférieur ou égal à 24FO | C20: =IF(OR($J20="",$J20=0),"",INDEX(BPU!$G$2:$G$117,$J20)&"") -> u (à la fibre) | D20: 24 | E20: =IF($B20="","",IF($J20=0,"Hors BPU",IF(ISNUMBER($K20),ROUND($K20,2),$K20))) -> 4.5 | H20: =IF($B20="","",IF(AND($F20="",NOT(ISNUMBER($E20))),"PU à saisir",ROUND(N($D20)*IF($F20<>"",$F20,$E20)*IF($G20="",1,IFERROR(INDEX(Majorations!$C$2:$C$3,MATCH($G20,ListeMajorations,0)),1)),2))) -> 108 | J20: =IF($B20="","",IFERROR(MATCH($B20,ListePrestations,0),0)) -> 91 | K20: =IF(OR($J20="",$J20=0),"",INDEX(BPU!$H$2:$H$117,$J20)) -> 4.5
A21: =IF($B21="","",COUNTA($B$15:$B21)) | C21: =IF(OR($J21="",$J21=0),"",INDEX(BPU!$G$2:$G$117,$J21)&"") | E21: =IF($B21="","",IF($J21=0,"Hors BPU",IF(ISNUMBER($K21),ROUND($K21,2),$K21))) | H21: =IF($B21="","",IF(AND($F21="",NOT(ISNUMBER($E21))),"PU à saisir",ROUND(N($D21)*IF($F21<>"",$F21,$E21)*IF($G21="",1,IFERROR(INDEX(Majorations!$C$2:$C$3,MATCH($G21,ListeMajorations,0)),1)),2))) | J21: =IF($B21="","",IFERROR(MATCH($B21,ListePrestations,0),0)) | K21: =IF(OR($J21="",$J21=0),"",INDEX(BPU!$H$2:$H$117,$J21))
A22: =IF($B22="","",COUNTA($B$15:$B22)) | C22: =IF(OR($J22="",$J22=0),"",INDEX(BPU!$G$2:$G$117,$J22)&"") | E22: =IF($B22="","",IF($J22=0,"Hors BPU",IF(ISNUMBER($K22),ROUND($K22,2),$K22))) | H22: =IF($B22="","",IF(AND($F22="",NOT(ISNUMBER($E22))),"PU à saisir",ROUND(N($D22)*IF($F22<>"",$F22,$E22)*IF($G22="",1,IFERROR(INDEX(Majorations!$C$2:$C$3,MATCH($G22,ListeMajorations,0)),1)),2))) | J22: =IF($B22="","",IFERROR(MATCH($B22,ListePrestations,0),0)) | K22: =IF(OR($J22="",$J22=0),"",INDEX(BPU!$H$2:$H$117,$J22))
A23: =IF($B23="","",COUNTA($B$15:$B23)) | C23: =IF(OR($J23="",$J23=0),"",INDEX(BPU!$G$2:$G$117,$J23)&"") | E23: =IF($B23="","",IF($J23=0,"Hors BPU",IF(ISNUMBER($K23),ROUND($K23,2),$K23))) | H23: =IF($B23="","",IF(AND($F23="",NOT(ISNUMBER($E23))),"PU à saisir",ROUND(N($D23)*IF($F23<>"",$F23,$E23)*IF($G23="",1,IFERROR(INDEX(Majorations!$C$2:$C$3,MATCH($G23,ListeMajorations,0)),1)),2))) | J23: =IF($B23="","",IFERROR(MATCH($B23,ListePrestations,0),0)) | K23: =IF(OR($J23="",$J23=0),"",INDEX(BPU!$H$2:$H$117,$J23))
A24: =IF($B24="","",COUNTA($B$15:$B24)) | C24: =IF(OR($J24="",$J24=0),"",INDEX(BPU!$G$2:$G$117,$J24)&"") | E24: =IF($B24="","",IF($J24=0,"Hors BPU",IF(ISNUMBER($K24),ROUND($K24,2),$K24))) | H24: =IF($B24="","",IF(AND($F24="",NOT(ISNUMBER($E24))),"PU à saisir",ROUND(N($D24)*IF($F24<>"",$F24,$E24)*IF($G24="",1,IFERROR(INDEX(Majorations!$C$2:$C$3,MATCH($G24,ListeMajorations,0)),1)),2))) | J24: =IF($B24="","",IFERROR(MATCH($B24,ListePrestations,0),0)) | K24: =IF(OR($J24="",$J24=0),"",INDEX(BPU!$H$2:$H$117,$J24))
A25: =IF($B25="","",COUNTA($B$15:$B25)) | C25: =IF(OR($J25="",$J25=0),"",INDEX(BPU!$G$2:$G$117,$J25)&"") | E25: =IF($B25="","",IF($J25=0,"Hors BPU",IF(ISNUMBER($K25),ROUND($K25,2),$K25))) | H25: =IF($B25="","",IF(AND($F25="",NOT(ISNUMBER($E25))),"PU à saisir",ROUND(N($D25)*IF($F25<>"",$F25,$E25)*IF($G25="",1,IFERROR(INDEX(Majorations!$C$2:$C$3,MATCH($G25,ListeMajorations,0)),1)),2))) | J25: =IF($B25="","",IFERROR(MATCH($B25,ListePrestations,0),0)) | K25: =IF(OR($J25="",$J25=0),"",INDEX(BPU!$H$2:$H$117,$J25))
A26: =IF($B26="","",COUNTA($B$15:$B26)) | C26: =IF(OR($J26="",$J26=0),"",INDEX(BPU!$G$2:$G$117,$J26)&"") | E26: =IF($B26="","",IF($J26=0,"Hors BPU",IF(ISNUMBER($K26),ROUND($K26,2),$K26))) | H26: =IF($B26="","",IF(AND($F26="",NOT(ISNUMBER($E26))),"PU à saisir",ROUND(N($D26)*IF($F26<>"",$F26,$E26)*IF($G26="",1,IFERROR(INDEX(Majorations!$C$2:$C$3,MATCH($G26,ListeMajorations,0)),1)),2))) | J26: =IF($B26="","",IFERROR(MATCH($B26,ListePrestations,0),0)) | K26: =IF(OR($J26="",$J26=0),"",INDEX(BPU!$H$2:$H$117,$J26))
A27: =IF($B27="","",COUNTA($B$15:$B27)) | C27: =IF(OR($J27="",$J27=0),"",INDEX(BPU!$G$2:$G$117,$J27)&"") | E27: =IF($B27="","",IF($J27=0,"Hors BPU",IF(ISNUMBER($K27),ROUND($K27,2),$K27))) | H27: =IF($B27="","",IF(AND($F27="",NOT(ISNUMBER($E27))),"PU à saisir",ROUND(N($D27)*IF($F27<>"",$F27,$E27)*IF($G27="",1,IFERROR(INDEX(Majorations!$C$2:$C$3,MATCH($G27,ListeMajorations,0)),1)),2))) | J27: =IF($B27="","",IFERROR(MATCH($B27,ListePrestations,0),0)) | K27: =IF(OR($J27="",$J27=0),"",INDEX(BPU!$H$2:$H$117,$J27))
A28: =IF($B28="","",COUNTA($B$15:$B28)) | C28: =IF(OR($J28="",$J28=0),"",INDEX(BPU!$G$2:$G$117,$J28)&"") | E28: =IF($B28="","",IF($J28=0,"Hors BPU",IF(ISNUMBER($K28),ROUND($K28,2),$K28))) | H28: =IF($B28="","",IF(AND($F28="",NOT(ISNUMBER($E28))),"PU à saisir",ROUND(N($D28)*IF($F28<>"",$F28,$E28)*IF($G28="",1,IFERROR(INDEX(Majorations!$C$2:$C$3,MATCH($G28,ListeMajorations,0)),1)),2))) | J28: =IF($B28="","",IFERROR(MATCH($B28,ListePrestations,0),0)) | K28: =IF(OR($J28="",$J28=0),"",INDEX(BPU!$H$2:$H$117,$J28))
A29: =IF($B29="","",COUNTA($B$15:$B29)) | C29: =IF(OR($J29="",$J29=0),"",INDEX(BPU!$G$2:$G$117,$J29)&"") | E29: =IF($B29="","",IF($J29=0,"Hors BPU",IF(ISNUMBER($K29),ROUND($K29,2),$K29))) | H29: =IF($B29="","",IF(AND($F29="",NOT(ISNUMBER($E29))),"PU à saisir",ROUND(N($D29)*IF($F29<>"",$F29,$E29)*IF($G29="",1,IFERROR(INDEX(Majorations!$C$2:$C$3,MATCH($G29,ListeMajorations,0)),1)),2))) | J29: =IF($B29="","",IFERROR(MATCH($B29,ListePrestations,0),0)) | K29: =IF(OR($J29="",$J29=0),"",INDEX(BPU!$H$2:$H$117,$J29))
A30: =IF($B30="","",COUNTA($B$15:$B30)) | C30: =IF(OR($J30="",$J30=0),"",INDEX(BPU!$G$2:$G$117,$J30)&"") | E30: =IF($B30="","",IF($J30=0,"Hors BPU",IF(ISNUMBER($K30),ROUND($K30,2),$K30))) | H30: =IF($B30="","",IF(AND($F30="",NOT(ISNUMBER($E30))),"PU à saisir",ROUND(N($D30)*IF($F30<>"",$F30,$E30)*IF($G30="",1,IFERROR(INDEX(Majorations!$C$2:$C$3,MATCH($G30,ListeMajorations,0)),1)),2))) | J30: =IF($B30="","",IFERROR(MATCH($B30,ListePrestations,0),0)) | K30: =IF(OR($J30="",$J30=0),"",INDEX(BPU!$H$2:$H$117,$J30))
A31: =IF($B31="","",COUNTA($B$15:$B31)) | C31: =IF(OR($J31="",$J31=0),"",INDEX(BPU!$G$2:$G$117,$J31)&"") | E31: =IF($B31="","",IF($J31=0,"Hors BPU",IF(ISNUMBER($K31),ROUND($K31,2),$K31))) | H31: =IF($B31="","",IF(AND($F31="",NOT(ISNUMBER($E31))),"PU à saisir",ROUND(N($D31)*IF($F31<>"",$F31,$E31)*IF($G31="",1,IFERROR(INDEX(Majorations!$C$2:$C$3,MATCH($G31,ListeMajorations,0)),1)),2))) | J31: =IF($B31="","",IFERROR(MATCH($B31,ListePrestations,0),0)) | K31: =IF(OR($J31="",$J31=0),"",INDEX(BPU!$H$2:$H$117,$J31))
A32: =IF($B32="","",COUNTA($B$15:$B32)) | C32: =IF(OR($J32="",$J32=0),"",INDEX(BPU!$G$2:$G$117,$J32)&"") | E32: =IF($B32="","",IF($J32=0,"Hors BPU",IF(ISNUMBER($K32),ROUND($K32,2),$K32))) | H32: =IF($B32="","",IF(AND($F32="",NOT(ISNUMBER($E32))),"PU à saisir",ROUND(N($D32)*IF($F32<>"",$F32,$E32)*IF($G32="",1,IFERROR(INDEX(Majorations!$C$2:$C$3,MATCH($G32,ListeMajorations,0)),1)),2))) | J32: =IF($B32="","",IFERROR(MATCH($B32,ListePrestations,0),0)) | K32: =IF(OR($J32="",$J32=0),"",INDEX(BPU!$H$2:$H$117,$J32))
... A44: =IF($B44="","",COUNTA($B$15:$B44)) | C44: =IF(OR($J44="",$J44=0),"",INDEX(BPU!$G$2:$G$117,$J44)&"") | E44: =IF($B44="","",IF($J44=0,"Hors BPU",IF(ISNUMBER($K44),ROUND($K44,2),$K44))) | H44: =IF($B44="","",IF(AND($F44="",NOT(ISNUMBER($E44))),"PU à saisir",ROUND(N($D44)*IF($F44<>"",$F44,$E44)*IF($G44="",1,IFERROR(INDEX(Majorations!$C$2:$C$3,MATCH($G44,ListeMajorations,0)),1)),2))) | J44: =IF($B44="","",IFERROR(MATCH($B44,ListePrestations,0),0)) | K44: =IF(OR($J44="",$J44=0),"",INDEX(BPU!$H$2:$H$117,$J44))
A46: =IF(COUNTIF(H15:H44,"PU à saisir")>0,"Attention : "&COUNTIF(H15:H44,"PU à saisir")&" ligne(s) sur devis sans prix, à compléter dans la colonne « PU HT sur devis ».","") | G46: Total HT | H46: =SUM(H15:H44) -> 1241.52
A47: =IF(COUNTA(G15:G44)=0,"","Majorations BPU appliquées au montant de la ligne : MC-07 × "&FIXED(Majorations!$C$2,4)&" ; MC-08 × "&FIXED(Majorations!$C$3,4)&".") -> Majorations BPU appliquées au montant de la ligne : MC-07 × 1.4906 ; MC-08 × 1.4078. | G47: =IF(Autoliq="Oui","TVA (autoliquidation)","TVA "&TauxTVA*100&" %") -> TVA 20 % | H47: =IF(Autoliq="Oui",0,ROUND(H46*TauxTVA,2)) -> 248.3
A48: =IF(Autoliq="Oui","Autoliquidation : TVA due par le preneur (article 283-2 nonies du CGI).","") | G48: Total TTC | H48: =H46+H47 -> 1489.82
A50: CONDITIONS
A51: Prix unitaires HT issus du BPU Moselle Fibre – RHD57 (Maintenance et VDR Optique).
A52: Hors fourniture, sauf mention contraire du BPU.
A53: Conditions de paiement : à préciser.
...

Sheet BPU
A1: BPU | B1: Lot | C1: Famille | D1: Code | E1: Désignation | F1: Descriptif | G1: Unité | H1: Prix BPU € HT / u | I1: Commentaire | J1: Libellé dans le devis | K1: Source
A2: Maintenance | B2: Rémunération et conditions de paiement au titre des Prestations de raccordements des clients | C2: Raccordements | D2: RA-F1 | E2: Raccordement abonné Opera Pro (PM) | F2: Aiguillage, Tirage , Racco et mise en service quelque soit la distance et le type de raccordement ( Souterrain , Aérien,Façade, Immeuble) | G2: Forfait par opération | H2: 210 | I2: à l'acte | J2: RA-F1 · Raccordement abonné Opera Pro (PM) | K2: Maintenance BPU ST · BPU ligne 4
A3: Maintenance | B3: Rémunération et conditions de paiement au titre des Prestations de raccordements des clients | C3: Raccordements | D3: RA-F2 | E3: Raccordement abonné Opera Office (PM) | F3: Aiguillage, Tirage , Racco et mise en service quelque soit la distance et le type de raccordement ( Souterrain , Aérien,Façade, Immeuble) | G3: Forfait par opération | H3: 210 | I3: à l'acte | J3: RA-F2 · Raccordement abonné Opera Office (PM) | K3: Maintenance BPU ST · BPU ligne 5
A4: Maintenance | B4: Rémunération et conditions de paiement au titre des Prestations de raccordements des clients | C4: Raccordements | D4: RA-F3 | E4: Raccordement abonné Opera Business BLOM (PM) | F4: Aiguillage, Tirage , Racco et mise en service quelque soit la distance et le type de raccordement ( Souterrain , Aérien,Façade, Immeuble) | G4: Forfait par opération | H4: 210 | I4: à l'acte | J4: RA-F3 · Raccordement abonné Opera Business BLOM (PM) | K4: Maintenance BPU ST · BPU ligne 6
A5: Maintenance | B5: Rémunération et conditions de paiement au titre des Prestations de raccordements des clients | C5: Raccordements | D5: RA-F4 | E5: Raccordement abonné Opera Business BLOM (NRO) | F5: Aiguillage, Tirage , Racco et mise en service quelque soit la distance et le type de raccordement ( Souterrain , Aérien,Façade, Immeuble) | G5: Forfait par opération | H5: 210 | I5: à l'acte | J5: RA-F4 · Raccordement abonné Opera Business BLOM (NRO) | K5: Maintenance BPU ST · BPU ligne 7
A6: Maintenance | B6: Rémunération et conditions de paiement au titre des Prestations de raccordements des clients | C6: Raccordements | D6: RA-ON | E6: Raccordement abonné Opera Business BLOD | F6: Pré-visite : reportage photos + aiguillage de la partie privée uniquement + CRVT : 108,45€ / MES : Aiguillage de la partie publique / Tirage et Raccordement + pose des équipements (PTO + ADVA) chez le client Aiguillage Hors founiture : 351,06€ / Jusqu'à 300ml ( 0,93€/ml au dela) | G6: Forfait par opération | H6: 459.51 | I6: à l'acte | J6: RA-ON · Raccordement abonné Opera Business BLOD | K6: Maintenance BPU ST · BPU ligne 8
A7: Maintenance | B7: Rémunération et conditions de paiement au titre des Prestations de raccordements des clients | C7: Raccordements | D7: RA-ON | E7: Raccordement abonné Opera Business BLOD – ml au-delà de 300 ml | F7: Mètre linéaire au-delà des 300 ml compris dans le forfait | G7: ml | H7: 0.93 | I7: D'après le descriptif de RA-ON (« jusqu'à 300ml, 0,93€/ml au-delà ») | J7: RA-ON · Raccordement abonné Opera Business BLOD – ml au-delà de 300 ml | K7: Maintenance BPU ST · BPU ligne 8
A8: Maintenance | B8: Rémunération et conditions de paiement au titre des Prestations de raccordements des clients | C8: Raccordements | D8: RA-B1 | E8: Raccordement Service à destination des personnes âgées en situation de dépendance (BLOM) | F8: Aiguillage, Tirage , Racco et mise en service quelque soit la distance et le type de raccordement ( Souterrain , Aérien,Façade, Immeuble) | G8: Forfait par opération | H8: 210 | I8: à l'acte | J8: RA-B1 · Raccordement Service à destination des personnes âgées en situation de dépendance (BLOM) | K8: Maintenance BPU ST · BPU ligne 9
A9: Maintenance | B9: Rémunération et conditions de paiement au titre des Prestations de raccordements des clients | C9: Raccordements | D9: RA-ON | E9: Churn Opéra Pro | F9: Mise en place d'une Jarretierage au POP/NRO/PM + Pose ONT/PTO chez le client pour MES | G9: Forfait par opération | H9: 50.1875 | I9: à l'acte | J9: RA-ON · Churn Opéra Pro | K9: Maintenance BPU ST · BPU ligne 10
A10: Maintenance | B10: Rémunération et conditions de paiement au titre des Prestations de raccordements des clients | C10: Raccordements | D10: RA-B1 | E10: Churn Opéra Office | F10: Mise en place d'une Jarretierage au POP/NRO/PM + Pose ONT/PTO chez le client pour MES | G10: Forfait par opération | H10: 50.1875 | I10: à l'acte | J10: RA-B1 · Churn Opéra Office | K10: Maintenance BPU ST · BPU ligne 11
A11: Maintenance | B11: Rémunération et conditions de paiement au titre des Prestations de raccordements des clients | C11: Raccordements | D11: RA-B2 | E11: Churn Opéra Business | F11: Mise en place d'une Jarretierage au POP/NRO/PM + Pose ONT/PTO chez le client pour MES | G11: Forfait par opération | H11: 50.1875 | I11: à l'acte | J11: RA-B2 · Churn Opéra Business | K11: Maintenance BPU ST · BPU ligne 12
A12: Maintenance | B12: Rémunération et conditions de paiement au titre des Prestations de raccordements des clients | C12: Raccordements | D12: RA-RO | E12: Raccordement abonné FttO - Zone 0 (BLOD) | G12: Forfait par opération | H12: Sur devis | I12: à l'acte | J12: RA-RO · Raccordement abonné FttO - Zone 0 (BLOD) | K12: Maintenance BPU ST · BPU ligne 13
A13: Maintenance | B13: Rémunération et conditions de paiement au titre des Prestations de raccordements des clients | C13: Raccordements | D13: RA-RO | E13: Raccordement abonné FttO - Zone 1 (BLOD) | G13: Forfait par opération | H13: Sur devis | I13: à l'acte | J13: RA-RO · Raccordement abonné FttO - Zone 1 (BLOD) | K13: Maintenance BPU ST · BPU ligne 14
A14: Maintenance | B14: Rémunération et conditions de paiement au titre des Prestations de raccordements des clients | C14: Raccordements | D14: RA-RO | E14: Raccordement abonné FttO - Zone 2 (BLOD) | G14: Forfait par opération | H14: Sur devis | I14: à l'acte | J14: RA-RO · Raccordement abonné FttO - Zone 2 (BLOD) | K14: Maintenance BPU ST · BPU ligne 15
A15: Maintenance | B15: Rémunération et conditions de paiement au titre des prestations de maintenance | C15: Astreinte | D15: AS-01 | E15: Forfait mensuel pour mise à disposition d'une astreinte d'un technicien équipé | G15: Forfait global Mensuel | H15: 500 | I15: Forfait mensuel | J15: AS-01 · Forfait mensuel pour mise à disposition d'une astreinte d'un technicien équipé | K15: Maintenance BPU ST · BPU ligne 18
A16: Maintenance | B16: Rémunération et conditions de paiement au titre des prestations de maintenance | C16: Astreinte | D16: AS-02 | E16: Forfait mensuel pour mise à disposition d'un 2 ème technicien d'astreinte équipé | G16: Forfait global Mensuel | H16: 300 | I16: Forfait mensuel | J16: AS-02 · Forfait mensuel pour mise à disposition d'un 2 ème technicien d'astreinte équipé | K16: Maintenance BPU ST · BPU ligne 19
A17: Maintenance | B17: Rémunération et conditions de paiement au titre des prestations de maintenance | C17: Mini-forfait curatif | D17: MC-01 | E17: Intervention Immédiate en HO TELECOM - opérations sur equipement actif | G17: Forfait par intervention | H17: 160.34179 | I17: à l'acte | J17: MC-01 · Intervention Immédiate en HO TELECOM - opérations sur equipement actif | K17: Maintenance BPU ST · BPU ligne 22
A18: Maintenance | B18: Rémunération et conditions de paiement au titre des prestations de maintenance | C18: Mini-forfait curatif | D18: MC-02 | E18: Intervention Programmée en HO TELECOM - opérations sur equipement actif | G18: Forfait par intervention | H18: 137.72096 | I18: à l'acte | J18: MC-02 · Intervention Programmée en HO TELECOM - opérations sur equipement actif | K18: Maintenance BPU ST · BPU ligne 23
A19: Maintenance | B19: Rémunération et conditions de paiement au titre des prestations de maintenance | C19: Mini-forfait curatif | D19: MC-03 | E19: Intervention Immédiate en HO ENVIRONNEMENT - énergie, climatisation, contrôle d'accès | G19: Forfait par intervention | H19: 141.71287 | I19: à l'acte | J19: MC-03 · Intervention Immédiate en HO ENVIRONNEMENT - énergie, climatisation, contrôle d'accès | K19: Maintenance BPU ST · BPU ligne 24
A20: Maintenance | B20: Rémunération et conditions de paiement au titre des prestations de maintenance | C20: Mini-forfait curatif | D20: MC-04 | E20: Intervention Programmée en HO ENVIRONNEMENT - énergie, climatisation, contrôle d'accès | G20: Forfait par intervention | H20: 86.491422 | I20: à l'acte | J20: MC-04 · Intervention Programmée en HO ENVIRONNEMENT - énergie, climatisation, contrôle d'accès | K20: Maintenance BPU ST · BPU ligne 25
A21: Maintenance | B21: Rémunération et conditions de paiement au titre des prestations de maintenance | C21: Mini-forfait curatif | D21: MC-05 | E21: SAV et ticket à froid yc. Intervention d'un technicien en HO | G21: Forfait par intervention | H21: 50.5 | I21: à l'acte | J21: MC-05 · SAV et ticket à froid yc. Intervention d'un technicien en HO | K21: Maintenance BPU ST · BPU ligne 26
A22: Maintenance | B22: Rémunération et conditions de paiement au titre des prestations de maintenance | C22: Mini-forfait curatif | D22: MC-06 | E22: SAV et ticket à froid yc. Intervention de deux techniciens (nacelle incluse) en HO | G22: Forfait par intervention | H22: 163.62 | I22: à l'acte | J22: MC-06 · SAV et ticket à froid yc. Intervention de deux techniciens (nacelle incluse) en HO | K22: Maintenance BPU ST · BPU ligne 27
A23: Maintenance | B23: Rémunération et conditions de paiement au titre des prestations de maintenance | C23: Mini-forfait curatif | D23: MC-09 | E23: SAV GTR 10h : Intervention d'un technicien en HO | G23: Forfait par intervention | H23: 50.5 | I23: à l'acte | J23: MC-09 · SAV GTR 10h : Intervention d'un technicien en HO | K23: Maintenance BPU ST · BPU ligne 30
A24: Maintenance | B24: Rémunération et conditions de paiement au titre des prestations de maintenance | C24: Mini-forfait curatif | D24: MC-10 | E24: SAV GTR 10h : Intervention de deux techniciens (nacelle incluse) en HO | G24: Forfait par intervention | H24: 163.62 | I24: à l'acte | J24: MC-10 · SAV GTR 10h : Intervention de deux techniciens (nacelle incluse) en HO | K24: Maintenance BPU ST · BPU ligne 31
A25: Maintenance | B25: Rémunération et conditions de paiement au titre des prestations de maintenance | C25: Maintenance curative | D25: MC-T1 | E25: Heure de technicien équipé en HO (8h00 – 18h00) - Intervention Immédiate | G25: Forfait par heure | H25: 35.92625 | I25: à l'acte | J25: MC-T1 · Heure de technicien équipé en HO (8h00 – 18h00) - Intervention Immédiate | K25: Maintenance BPU ST · BPU ligne 33
A26: Maintenance | B26: Rémunération et conditions de paiement au titre des prestations de maintenance | C26: Maintenance curative | D26: MC-T2 | E26: Heure de technicien équipé en HO (8h00 – 18h00) - Intervention Programmée | G26: Forfait par heure | H26: 35.05125 | I26: à l'acte | J26: MC-T2 · Heure de technicien équipé en HO (8h00 – 18h00) - Intervention Programmée | K26: Maintenance BPU ST · BPU ligne 34
... A29: Maintenance | B29: Rémunération et conditions de paiement au titre des prestations de maintenance | C29: Maintenance curative | D29: MC-T5 | E29: Intervention de 2 techniciens équipés d'une nacelle <= 16m en HNO | G29: Forfait par heure | H29: 123.75 | I29: à l'acte | J29: MC-T5 · Intervention de 2 techniciens équipés d'une nacelle <= 16m en HNO | K29: Maintenance BPU ST · BPU ligne 37
A30: Maintenance | B30: Rémunération et conditions de paiement au titre des prestations de maintenance | C30: Maintenance curative | D30: MC-T6 | E30: Mise à disposition d'une nacelle exceptionnelle (>16m, nacelle araignée, 4x4, inversée) - un jour | G30: Par mètre (hauteur nacelle) | H30: Sur devis | I30: à l'acte | J30: MC-T6 · Mise à disposition d'une nacelle exceptionnelle (>16m, nacelle araignée, 4x4, inversée) - un… | K30: Maintenance BPU ST · BPU ligne 38
A31: Maintenance | B31: Rémunération et conditions de paiement au titre des prestations de maintenance | C31: Commandes des usagers | D31: PU-01 | E31: Installation électrique au NRO yc. fourniture et pose du tiroir optique dans la baie de transport | G31: Par commande | H31: Sur devis | I31: à l'acte | J31: PU-01 · Installation électrique au NRO yc. fourniture et pose du tiroir optique dans la baie de… | K31: Maintenance BPU ST · BPU ligne 40
A32: Maintenance | B32: Rémunération et conditions de paiement au titre des prestations de maintenance | C32: Commandes des usagers | D32: PU-02 | E32: Fourniture et pose d'un tiroir optique dans la baie de transport | G32: Par commande | H32: Sur devis | I32: à l'acte | J32: PU-02 · Fourniture et pose d'un tiroir optique dans la baie de transport | K32: Maintenance BPU ST · BPU ligne 41
A33: Maintenance | B33: Rémunération et conditions de paiement au titre des prestations de maintenance | C33: Commandes des usagers | D33: PU-03 | E33: Fourniture et pose d’une jarretière entre la baie Opérateur et la baie OCEN | G33: Par commande | H33: Sur devis | I33: à l'acte | J33: PU-03 · Fourniture et pose d’une jarretière entre la baie Opérateur et la baie OCEN | K33: Maintenance BPU ST · BPU ligne 42
A34: Maintenance | B34: Rémunération et conditions de paiement au titre des prestations de maintenance | C34: Commandes des usagers | D34: PU-04 | E34: Fourniture et pose de jarretières entre la tête de câble OC et le tiroir transport PM dans le NRO | G34: Par commande | H34: Sur devis | I34: à l'acte | J34: PU-04 · Fourniture et pose de jarretières entre la tête de câble OC et le tiroir transport PM dans le… | K34: Maintenance BPU ST · BPU ligne 43
A35: Maintenance | B35: Rémunération et conditions de paiement au titre des prestations de maintenance | C35: Commandes des usagers | D35: PU-05 | E35: Fourniture et pose au NRO d'une baie 42U yc. raccordement du PDU | G35: Par commande | H35: Sur devis | I35: à l'acte | J35: PU-05 · Fourniture et pose au NRO d'une baie 42U yc. raccordement du PDU | K35: Maintenance BPU ST · BPU ligne 44
A36: Maintenance | B36: Rémunération et conditions de paiement au titre des prestations de maintenance | C36: Commandes des usagers | D36: PU-06 | E36: Fourniture et pose au NRO d'une baie 21U yc. raccordement du PDU | G36: Par commande | H36: Sur devis | I36: à l'acte | J36: PU-06 · Fourniture et pose au NRO d'une baie 21U yc. raccordement du PDU | K36: Maintenance BPU ST · BPU ligne 45
A37: VDR Optique | B37: 1 - Infrastructures tièrces | C37: 1 - Infrastructures tièrces | D37: 1.1 | E37: Aiguillage de génie civil sous-terrain existant | F37: Ce prix rémunère au métre mesuré sur place l'aiguillage de conduite existante (réseau Orange, ou tiers) afin de vérifier la disponibilité de cette conduite en vue d'un futur passage de câble et comprend: - l'aiguillage de la conduite existante - la pose d'un filin et étiquette - la détection des points de blocage - si nécessaire, le nettoyage manuel de la chambre | G37: ml | H37: 0.4 | J37: 1.1 · Aiguillage de génie civil sous-terrain existant | K37: BPU ST VDR Optique · BPU MISSION 3 Optique ligne 5
A38: VDR Optique | B38: 1 - Infrastructures tièrces | C38: 1 - Infrastructures tièrces | D38: 1.2 | E38: Débouchage de réseaux existants à l'aide d'un camion d'hydrocurage | F38: Ce prix rémunère à l'unité le débouchage d'une conduite obstruée comprenant: - une équipe pour accès aux regards - un camion d'hydrocurage avec son personnel spécialisé et habilité - redevance pour le traitement des déchets Ce prix tient compte de la fourniture et la mise en place des signalisations chantier (déviations éventuelles, alternats manuels K10,...). | G38: U | H38: 550 | J38: 1.2 · Débouchage de réseaux existants à l'aide d'un camion d'hydrocurage | K38: BPU ST VDR Optique · BPU MISSION 3 Optique ligne 6
A39: VDR Optique | B39: 1 - Infrastructures tièrces | C39: 1 - Infrastructures tièrces | D39: 1.3 | E39: Relevé de masques de chambre FT non plafonnée et édition de la fiche FOA conformément à l'offre de référence iBLO de France Télécom, hors aiguillage | G39: U | H39: 25 | J39: 1.3 · Relevé de masques de chambre FT non plafonnée et édition de la fiche FOA conformément à… | K39: BPU ST VDR Optique · BPU MISSION 3 Optique ligne 7
A40: VDR Optique | B40: 1 - Infrastructures tièrces | C40: 1 - Infrastructures tièrces | D40: 1.4 | E40: Relevé de masques de chambre FT plafonnée et édition de la fiche FOA conformément à l'offre de référence iBLO de France Télécom, hors aiguillage | G40: U | H40: 35 | J40: 1.4 · Relevé de masques de chambre FT plafonnée et édition de la fiche FOA conformément à l'offre de… | K40: BPU ST VDR Optique · BPU MISSION 3 Optique ligne 8
A41: VDR Optique | B41: 4 - Câbles optiques, étiquetage, DOE inclus | C41: 4.1 - Pose et dépose de câbles optiques pour pose en fourreau | D41: 4.1.1 | E41: Pose de câbles à fibres optiques, G657-A2 ou G652-D , de 1 FO à 144 FO | F41: Ce prix rémunère au métre mesuré sur place la pose en fourreau de cable comprenant : - la pose de cable à fibres optiques, - le matériel nécessaire à la mise en place (soufalge à l'aire ou à l'eau, etc) - la fourniture et la mise en place des signalisations chantier (déviations éventuelles, alternats manuels K10,... | G41: ml | H41: 1 | J41: 4.1.1 · Pose de câbles à fibres optiques, G657-A2 ou G652-D , de 1 FO à 144 FO | K41: BPU ST VDR Optique · BPU MISSION 3 Optique ligne 12
A42: VDR Optique | B42: 4 - Câbles optiques, étiquetage, DOE inclus | C42: 4.1 - Pose et dépose de câbles optiques pour pose en fourreau | D42: 4.1.13 | E42: Pose de câbles à fibres optiques, G657-A2 ou G652-D , supérieur ou égal à 288FO | F42: Ce prix rémunère au métre mesuré sur place la pose en fourreau de cable comprenant : - la pose de cable à fibres optiques, - le matériel nécessaire à la mise en place (soufalge à l'aire ou à l'eau, etc) - la fourniture et la mise en place des signalisations chantier (déviations éventuelles, alternats manuels K10,... | G42: ml | H42: 1.2 | J42: 4.1.13 · Pose de câbles à fibres optiques, G657-A2 ou G652-D , supérieur ou égal à 288FO | K42: BPU ST VDR Optique · BPU MISSION 3 Optique ligne 13
...

Sheet Majorations
A1: Code | B1: Libellé dans le devis | C1: Coefficient | D1: Unité | E1: Commentaire | F1: Source
A2: MC-07 | B2: MC-07 · Technicien supplémentaire | C2: 1.4906176 | D2: coef. appliqué au forfait | E2: Majoration par technicien supplémentaire sur une intervention (à l'acte) | F2: Maintenance BPU ST · BPU ligne 28
A3: MC-08 | B3: MC-08 · Intervention en HNO | C3: 1.4078055 | D3: coef. appliqué au forfait | E3: Majoration en cas d'intervention en HNO (min 20% de l'inter. en HNO) (à l'acte) | F3: Maintenance BPU ST · BPU ligne 29
A5: Le montant de la ligne du devis est multiplié par le coefficient (ex. 1,4078 = +40,78 %).
